Workbook

Sheet 更新履歴
A1: 更新履歴
A4: № | C4: 更新日付 | G4: 更新資料（シート名） | M4: 更新内容 | AB4: 更新者名 | AF4: 備考
A5: =IF(M5="","",ROW()-4) -> 1 | C5: 42917 | G5: 全シート | M5: 初版 | AB5: 富士通）西浦
A6: =IF(M6="","",ROW()-4)
A7: =IF(M7="","",ROW()-4)
A8: =IF(M8="","",ROW()-4)
A9: =IF(M9="","",ROW()-4)
A10: =IF(M10="","",ROW()-4)
A11: =IF(M11="","",ROW()-4)
A12: =IF(M12="","",ROW()-4)
A13: =IF(M13="","",ROW()-4)
A14: =IF(M14="","",ROW()-4)
A15: =IF(M15="","",ROW()-4)
A16: =IF(M16="","",ROW()-4)
A17: =IF(M17="","",ROW()-4)
... A33: =IF(M33="","",ROW()-4)

Sheet カラムID辞書
A1: カラムID辞書 | I1: 文字コード(UTF-8)
A2: 重複チェック | I2: 日本語平均使用率
A3: 論理名 | B3: 物理名 | C3: 項目論理名称 | D3: 項目物理名称 | E3: TYPE | F3: 桁数 | G3: ASCII以外 有無 | H3: BYTE | L3: RD工程 Type
A4: =COUNTIF($C$4:$C$1266,C4) -> 1 | B4: =COUNTIF($D$4:$D$1266,D4) -> 1 | C4: 年月日 | D4: YMD | E4: numeric | F4: 8 | H4: 8 | L4: NUMBER
A5: =COUNTIF($C$4:$C$1266,C5) -> 1 | B5: =COUNTIF($D$4:$D$1266,D5) -> 1 | C5: SEQ№ | D5: SEQNO | E5: numeric | F5: 2 | H5: 2 | I5: 合わない：商品明細ワークは8ケタ、５Byte | L5: NUMBER
A6: =COUNTIF($C$4:$C$1266,C6) -> 1 | B6: =COUNTIF($D$4:$D$1266,D6) -> 1 | C6: システムグループコード | D6: SYSGRPCD | E6: character varying | F6: 4 | H6: 4 | L6: VARCHAR2
A7: =COUNTIF($C$4:$C$1266,C7) -> 1 | B7: =COUNTIF($D$4:$D$1266,D7) -> 1 | C7: 企業グループコード | D7: KGYGRPCD | E7: character varying | F7: 3 | H7: 3 | L7: VARCHAR2
A8: =COUNTIF($C$4:$C$1266,C8) -> 1 | B8: =COUNTIF($D$4:$D$1266,D8) -> 1 | C8: 店コード | D8: TENCD | E8: character varying | F8: 4 | H8: 4 | L8: VARCHAR2
A9: =COUNTIF($C$4:$C$1266,C9) -> 1 | B9: =COUNTIF($D$4:$D$1266,D9) -> 1 | C9: 商品コード１ | D9: SHOHINCD1 | E9: character varying | F9: 6 | H9: 6 | L9: VARCHAR2
A10: =COUNTIF($C$4:$C$1266,C10) -> 1 | B10: =COUNTIF($D$4:$D$1266,D10) -> 1 | C10: 商品コード２ | D10: SHOHINCD2 | E10: character varying | F10: 6 | H10: 6 | L10: VARCHAR2
A11: =COUNTIF($C$4:$C$1266,C11) -> 1 | B11: =COUNTIF($D$4:$D$1266,D11) -> 1 | C11: 商品コード３ | D11: SHOHINCD3 | E11: character varying | F11: 6 | H11: 6 | L11: VARCHAR2
A12: =COUNTIF($C$4:$C$1266,C12) -> 1 | B12: =COUNTIF($D$4:$D$1266,D12) -> 1 | C12: 商品コード４ | D12: SHOHINCD4 | E12: character varying | F12: 6 | H12: 6 | L12: VARCHAR2
A13: =COUNTIF($C$4:$C$1266,C13) -> 1 | B13: =COUNTIF($D$4:$D$1266,D13) -> 1 | C13: 商品コード５ | D13: SHOHINCD5 | E13: character varying | F13: 6 | H13: 6 | L13: VARCHAR2
A14: =COUNTIF($C$4:$C$1266,C14) -> 1 | B14: =COUNTIF($D$4:$D$1266,D14) -> 1 | C14: 細別コード１ | D14: SIBTCD1 | E14: character varying | F14: 10 | H14: 10 | L14: VARCHAR2
A15: =COUNTIF($C$4:$C$1266,C15) -> 1 | B15: =COUNTIF($D$4:$D$1266,D15) -> 1 | C15: 細別コード２ | D15: SIBTCD2 | E15: character varying | F15: 10 | H15: 10 | L15: VARCHAR2
A16: =COUNTIF($C$4:$C$1266,C16) -> 1 | B16: =COUNTIF($D$4:$D$1266,D16) -> 1 | C16: 単品コード１ | D16: TNPNCD1 | E16: character varying | F16: 13 | H16: 13 | L16: VARCHAR2
A17: =COUNTIF($C$4:$C$1266,C17) -> 1 | B17: =COUNTIF($D$4:$D$1266,D17) -> 1 | C17: 単品コード２ | D17: TNPNCD2 | E17: character varying | F17: 13 | H17: 13 | L17: VARCHAR2
... A40: =COUNTIF($C$4:$C$1266,C40) -> 1 | B40: =COUNTIF($D$4:$D$1266,D40) -> 1 | C40: 値引額 | D40: NEBIKI_GAK | E40: numeric | F40: 13 | H40: 13 | L40: NUMBER
A41: =COUNTIF($C$4:$C$1266,C41) -> 1 | B41: =COUNTIF($D$4:$D$1266,D41) -> 1 | C41: 客数１ | D41: KYAKU1_SU | E41: numeric | F41: 10,2 | H41: 10 | L41: NUMBER
A42: =COUNTIF($C$4:$C$1266,C42) -> 1 | B42: =COUNTIF($D$4:$D$1266,D42) -> 1 | C42: 客数２ | D42: KYAKU2_SU | E42: numeric | F42: 10,2 | H42: 10 | L42: NUMBER
A43: =COUNTIF($C$4:$C$1266,C43) -> 1 | B43: =COUNTIF($D$4:$D$1266,D43) -> 1 | C43: 客数３ | D43: KYAKU3_SU | E43: numeric | F43: 10,2 | H43: 10 | L43: NUMBER
A44: =COUNTIF($C$4:$C$1266,C44) -> 1 | B44: =COUNTIF($D$4:$D$1266,D44) -> 1 | C44: 純仕入高原価 | D44: JNSHIIRED_GNK | E44: numeric | F44: 13 | H44: 13 | L44: NUMBER
A45: =COUNTIF($C$4:$C$1266,C45) -> 1 | B45: =COUNTIF($D$4:$D$1266,D45) -> 1 | C45: 純仕入高売価 | D45: JNSHIIRED_BIK | E45: numeric | F45: 13 | H45: 13 | L45: NUMBER
A46: =COUNTIF($C$4:$C$1266,C46) -> 1 | B46: =COUNTIF($D$4:$D$1266,D46) -> 1 | C46: 純仕入高数量 | D46: JNSHIIRED_SU | E46: numeric | F46: 10 | H46: 10 | L46: NUMBER
A47: =COUNTIF($C$4:$C$1266,C47) -> 1 | B47: =COUNTIF($D$4:$D$1266,D47) -> 1 | C47: 仕入高原価 | D47: SHIIRED_GNK | E47: numeric | F47: 13 | H47: 13 | L47: NUMBER
A48: =COUNTIF($C$4:$C$1266,C48) -> 1 | B48: =COUNTIF($D$4:$D$1266,D48) -> 1 | C48: 仕入高売価 | D48: SHIIRED_BIK | E48: numeric | F48: 13 | H48: 13 | L48: NUMBER
A49: =COUNTIF($C$4:$C$1266,C49) -> 1 | B49: =COUNTIF($D$4:$D$1266,D49) -> 1 | C49: 仕入高数量 | D49: SHIIRED_SU | E49: numeric | F49: 10 | H49: 10 | L49: NUMBER
A50: =COUNTIF($C$4:$C$1266,C50) -> 1 | B50: =COUNTIF($D$4:$D$1266,D50) -> 1 | C50: 付帯仕入高原価 | D50: FUTAISHIIRED_GNK | E50: numeric | F50: 13 | H50: 13 | L50: NUMBER
A51: =COUNTIF($C$4:$C$1266,C51) -> 1 | B51: =COUNTIF($D$4:$D$1266,D51) -> 1 | C51: 返品高原価 | D51: HENPND_GNK | E51: numeric | F51: 13 | H51: 13 | L51: NUMBER
A52: =COUNTIF($C$4:$C$1266,C52) -> 1 | B52: =COUNTIF($D$4:$D$1266,D52) -> 1 | C52: 返品高売価 | D52: HENPND_BIK | E52: numeric | F52: 13 | H52: 13 | L52: NUMBER
A53: =COUNTIF($C$4:$C$1266,C53) -> 1 | B53: =COUNTIF($D$4:$D$1266,D53) -> 1 | C53: 返品高数量 | D53: HENPND_SU | E53: numeric | F53: 10 | H53: 10 | L53: NUMBER
A54: =COUNTIF($C$4:$C$1266,C54) -> 1 | B54: =COUNTIF($D$4:$D$1266,D54) -> 1 | C54: 付帯返品高原価 | D54: FUTAIHENPND_GNK | E54: numeric | F54: 13 | H54: 13 | L54: NUMBER
A55: =COUNTIF($C$4:$C$1266,C55) -> 1 | B55: =COUNTIF($D$4:$D$1266,D55) -> 1 | C55: 価格訂正仕入高原価 | D55: TEISEISHIIRED_GNK | E55: numeric | F55: 13 | H55: 13 | L55: NUMBER
... A63: =COUNTIF($C$4:$C$1266,C63) -> 1 | B63: =COUNTIF($D$4:$D$1266,D63) -> 1 | C63: 値上高原価１ | D63: NEAGED1_GNK | E63: numeric | F63: 13 | H63: 13 | L63: NUMBER
A64: =COUNTIF($C$4:$C$1266,C64) -> 1 | B64: =COUNTIF($D$4:$D$1266,D64) -> 1 | C64: 値上高売価１ | D64: NEAGED1_BIK | E64: numeric | F64: 13 | H64: 13 | I64: 合わない：商品明細ワークは10ケタ、6Byte | L64: NUMBER
A65: =COUNTIF($C$4:$C$1266,C65) -> 1 | B65: =COUNTIF($D$4:$D$1266,D65) -> 1 | C65: 値下高原価１ | D65: NESAGED1_GNK | E65: numeric | F65: 13 | H65: 13 | L65: NUMBER
A66: =COUNTIF($C$4:$C$1266,C66) -> 1 | B66: =COUNTIF($D$4:$D$1266,D66) -> 1 | C66: 値下高売価１ | D66: NESAGED1_BIK | E66: numeric | F66: 13 | H66: 13 | I66: 合わない：商品明細ワークは10ケタ、6Byte | L66: NUMBER
A67: =COUNTIF($C$4:$C$1266,C67) -> 1 | B67: =COUNTIF($D$4:$D$1266,D67) -> 1 | C67: 値上高原価２ | D67: NEAGED2_GNK | E67: numeric | F67: 13 | H67: 13 | L67: NUMBER
A68: =COUNTIF($C$4:$C$1266,C68) -> 1 | B68: =COUNTIF($D$4:$D$1266,D68) -> 1 | C68: 値上高売価２ | D68: NEAGED2_BIK | E68: numeric | F68: 13 | H68: 13 | I68: 合わない：商品明細ワークは10ケタ、6Byte | L68: NUMBER
A69: =COUNTIF($C$4:$C$1266,C69) -> 1 | B69: =COUNTIF($D$4:$D$1266,D69) -> 1 | C69: 値下高原価２ | D69: NESAGED2_GNK | E69: numeric | F69: 13 | H69: 13 | L69: NUMBER
...

Sheet 売価還元単位別日別実績
B2: ユーザインタフェース 設計書 | J2: サブシステム分類 | O2: ドキュメント ID | T2: ドキュメント名 | BK2: 更新者 | BN2: 最終更新日 | BR2: 履歴 | BT2: 作成者 | BW2: 作成日
J3: 商品勘定 | O3: 2.04 | T3: テーブル定義 | BR3: 第1版 | BT3: 富士通 | BW3: 42917
B5: 概念データ名／ID | J5: 売価還元単位別日別実績テーブル | U5: ／ | V5: LBT01_BAIKAN_D | AD5: OID | AK5: 最大レコード長 | AR5: =ROUNDUP((27+ROUNDUP((MAX(B:B)-COUNTIF(AB:AB,"○"))/8,0)+IF(AF5="",0,4))/8,0)*8+SUM(AO8:AO1039) -> 1888 | AU5: Byte | AW5: 用途 | BB5: 商品勘定実績を日単位で管理する。
B7: 項番 | D7: 項目論理名称 | L7: 項目物理名称 | T7: PKey | V7: IDX1 | X7: IDX2 | Z7: IDX3 | AB7: NOTNULL | AE7: DEFAULT | AH7: Type | AM7: 桁数 | AO7: Byte | AQ7: 項目説明 | BR7: 備考
B8: 1 | D8: 年月日 | L8: =VLOOKUP(D8,カラムID辞書!$C$4:$D$1266,2,FALSE) -> YMD | T8: 1 | AB8: =IF(L8="DELDTE","","○") -> ○ | AE8: =IF(AB8="○",IF(AH8="timestamp","now()",IF(LEFT(AH8,9)="character","' '","0")),"") -> 0 | AH8: =VLOOKUP(D8,カラムID辞書!C:H,3,FALSE) -> numeric | AM8: =VLOOKUP(D8,カラムID辞書!C:H,4,FALSE) -> 8 | AO8: =VLOOKUP(D8,カラムID辞書!C:H,6,FALSE) -> 8 | AQ8: 伝票計上日（修正伝票は月末日）
B9: =IF($D9="","",MAX(OFFSET($B$8,0,0,ROW()-ROW($B$8),2))+1) -> 2 | D9: SEQ№ | L9: =VLOOKUP(D9,カラムID辞書!$C$4:$D$1266,2,FALSE) -> SEQNO | T9: 2 | AB9: =IF(L9="DELDTE","","○") -> ○ | AE9: =IF(AB9="○",IF(AH9="timestamp","now()",IF(LEFT(AH9,9)="character","' '","0")),"") -> 0 | AH9: =VLOOKUP(D9,カラムID辞書!C:H,3,FALSE) -> numeric | AM9: =VLOOKUP(D9,カラムID辞書!C:H,4,FALSE) -> 2 | AO9: =VLOOKUP(D9,カラムID辞書!C:H,6,FALSE) -> 2
B10: =IF($D10="","",MAX(OFFSET($B$8,0,0,ROW()-ROW($B$8),2))+1) -> 3 | D10: システムグループコード | L10: =VLOOKUP(D10,カラムID辞書!$C$4:$D$1266,2,FALSE) -> SYSGRPCD | T10: 3 | AB10: =IF(L10="DELDTE","","○") -> ○ | AE10: =IF(AB10="○",IF(AH10="timestamp","now()",IF(LEFT(AH10,9)="character","' '","0")),"") -> ' ' | AH10: =VLOOKUP(D10,カラムID辞書!C:H,3,FALSE) -> character varying | AM10: =VLOOKUP(D10,カラムID辞書!C:H,4,FALSE) -> 4 | AO10: =VLOOKUP(D10,カラムID辞書!C:H,6,FALSE) -> 4 | AQ10: ユーザ分類コード | BR10: "0010"固定
B11: =IF($D11="","",MAX(OFFSET($B$8,0,0,ROW()-ROW($B$8),2))+1) -> 4 | D11: 企業グループコード | L11: =VLOOKUP(D11,カラムID辞書!$C$4:$D$1266,2,FALSE) -> KGYGRPCD | T11: 4 | AB11: =IF(L11="DELDTE","","○") -> ○ | AE11: =IF(AB11="○",IF(AH11="timestamp","now()",IF(LEFT(AH11,9)="character","' '","0")),"") -> ' ' | AH11: =VLOOKUP(D11,カラムID辞書!C:H,3,FALSE) -> character varying | AM11: =VLOOKUP(D11,カラムID辞書!C:H,4,FALSE) -> 3 | AO11: =VLOOKUP(D11,カラムID辞書!C:H,6,FALSE) -> 3 | AQ11: 売上、仕入伝票の企業グループコード
B12: =IF($D12="","",MAX(OFFSET($B$8,0,0,ROW()-ROW($B$8),2))+1) -> 5 | D12: 店コード | L12: =VLOOKUP(D12,カラムID辞書!$C$4:$D$1266,2,FALSE) -> TENCD | T12: 5 | AB12: =IF(L12="DELDTE","","○") -> ○ | AE12: =IF(AB12="○",IF(AH12="timestamp","now()",IF(LEFT(AH12,9)="character","' '","0")),"") -> ' ' | AH12: =VLOOKUP(D12,カラムID辞書!C:H,3,FALSE) -> character varying | AM12: =VLOOKUP(D12,カラムID辞書!C:H,4,FALSE) -> 4 | AO12: =VLOOKUP(D12,カラムID辞書!C:H,6,FALSE) -> 4 | AQ12: 売上、仕入伝票の店コード
B13: =IF($D13="","",MAX(OFFSET($B$8,0,0,ROW()-ROW($B$8),2))+1) -> 6 | D13: 商品コード１ | L13: =VLOOKUP(D13,カラムID辞書!$C$4:$D$1266,2,FALSE) -> SHOHINCD1 | T13: 6 | AB13: =IF(L13="DELDTE","","○") -> ○ | AE13: =IF(AB13="○",IF(AH13="timestamp","now()",IF(LEFT(AH13,9)="character","' '","0")),"") -> ' ' | AH13: =VLOOKUP(D13,カラムID辞書!C:H,3,FALSE) -> character varying | AM13: =VLOOKUP(D13,カラムID辞書!C:H,4,FALSE) -> 6 | AO13: =VLOOKUP(D13,カラムID辞書!C:H,6,FALSE) -> 6 | AQ13: 売上、仕入伝票の商品コード１ | BR13: 品番
B14: =IF($D14="","",MAX(OFFSET($B$8,0,0,ROW()-ROW($B$8),2))+1) -> 7 | D14: 商品コード２ | L14: =VLOOKUP(D14,カラムID辞書!$C$4:$D$1266,2,FALSE) -> SHOHINCD2 | T14: 7 | AB14: =IF(L14="DELDTE","","○") -> ○ | AE14: =IF(AB14="○",IF(AH14="timestamp","now()",IF(LEFT(AH14,9)="character","' '","0")),"") -> ' ' | AH14: =VLOOKUP(D14,カラムID辞書!C:H,3,FALSE) -> character varying | AM14: =VLOOKUP(D14,カラムID辞書!C:H,4,FALSE) -> 6 | AO14: =VLOOKUP(D14,カラムID辞書!C:H,6,FALSE) -> 6 | AQ14: 売上、仕入伝票の商品コード２ | BR14: （未設定）
B15: =IF($D15="","",MAX(OFFSET($B$8,0,0,ROW()-ROW($B$8),2))+1) -> 8 | D15: 商品コード３ | L15: =VLOOKUP(D15,カラムID辞書!$C$4:$D$1266,2,FALSE) -> SHOHINCD3 | T15: 8 | AB15: =IF(L15="DELDTE","","○") -> ○ | AE15: =IF(AB15="○",IF(AH15="timestamp","now()",IF(LEFT(AH15,9)="character","' '","0")),"") -> ' ' | AH15: =VLOOKUP(D15,カラムID辞書!C:H,3,FALSE) -> character varying | AM15: =VLOOKUP(D15,カラムID辞書!C:H,4,FALSE) -> 6 | AO15: =VLOOKUP(D15,カラムID辞書!C:H,6,FALSE) -> 6 | AQ15: 売上、仕入伝票の商品コード３ | BR15: （未設定）
B16: =IF($D16="","",MAX(OFFSET($B$8,0,0,ROW()-ROW($B$8),2))+1) -> 9 | D16: 商品コード４ | L16: =VLOOKUP(D16,カラムID辞書!$C$4:$D$1266,2,FALSE) -> SHOHINCD4 | T16: 9 | AB16: =IF(L16="DELDTE","","○") -> ○ | AE16: =IF(AB16="○",IF(AH16="timestamp","now()",IF(LEFT(AH16,9)="character","' '","0")),"") -> ' ' | AH16: =VLOOKUP(D16,カラムID辞書!C:H,3,FALSE) -> character varying | AM16: =VLOOKUP(D16,カラムID辞書!C:H,4,FALSE) -> 6 | AO16: =VLOOKUP(D16,カラムID辞書!C:H,6,FALSE) -> 6 | AQ16: 売上、仕入伝票の商品コード４ | BR16: （未設定）
B17: =IF($D17="","",MAX(OFFSET($B$8,0,0,ROW()-ROW($B$8),2))+1) -> 10 | D17: 商品コード５ | L17: =VLOOKUP(D17,カラムID辞書!$C$4:$D$1266,2,FALSE) -> SHOHINCD5 | T17: 10 | AB17: =IF(L17="DELDTE","","○") -> ○ | AE17: =IF(AB17="○",IF(AH17="timestamp","now()",IF(LEFT(AH17,9)="character","' '","0")),"") -> ' ' | AH17: =VLOOKUP(D17,カラムID辞書!C:H,3,FALSE) -> character varying | AM17: =VLOOKUP(D17,カラムID辞書!C:H,4,FALSE) -> 6 | AO17: =VLOOKUP(D17,カラムID辞書!C:H,6,FALSE) -> 6 | AQ17: 売上、仕入伝票の商品コード５ | BR17: （未設定）
B18: =IF($D18="","",MAX(OFFSET($B$8,0,0,ROW()-ROW($B$8),2))+1) -> 11 | D18: 細別コード１ | L18: =VLOOKUP(D18,カラムID辞書!$C$4:$D$1266,2,FALSE) -> SIBTCD1 | T18: 11 | AB18: =IF(L18="DELDTE","","○") -> ○ | AE18: =IF(AB18="○",IF(AH18="timestamp","now()",IF(LEFT(AH18,9)="character","' '","0")),"") -> ' ' | AH18: =VLOOKUP(D18,カラムID辞書!C:H,3,FALSE) -> character varying | AM18: =VLOOKUP(D18,カラムID辞書!C:H,4,FALSE) -> 10 | AO18: =VLOOKUP(D18,カラムID辞書!C:H,6,FALSE) -> 10 | AQ18: 売上、仕入伝票の細別コード１ | BR18: （未設定）
B19: =IF($D19="","",MAX(OFFSET($B$8,0,0,ROW()-ROW($B$8),2))+1) -> 12 | D19: 細別コード２ | L19: =VLOOKUP(D19,カラムID辞書!$C$4:$D$1266,2,FALSE) -> SIBTCD2 | T19: 12 | AB19: =IF(L19="DELDTE","","○") -> ○ | AE19: =IF(AB19="○",IF(AH19="timestamp","now()",IF(LEFT(AH19,9)="character","' '","0")),"") -> ' ' | AH19: =VLOOKUP(D19,カラムID辞書!C:H,3,FALSE) -> character varying | AM19: =VLOOKUP(D19,カラムID辞書!C:H,4,FALSE) -> 10 | AO19: =VLOOKUP(D19,カラムID辞書!C:H,6,FALSE) -> 10 | AQ19: 売上、仕入伝票の細別コード２ | BR19: （未設定）
B20: =IF($D20="","",MAX(OFFSET($B$8,0,0,ROW()-ROW($B$8),2))+1) -> 13 | D20: 単品コード１ | L20: =VLOOKUP(D20,カラムID辞書!$C$4:$D$1266,2,FALSE) -> TNPNCD1 | T20: 13 | AB20: =IF(L20="DELDTE","","○") -> ○ | AE20: =IF(AB20="○",IF(AH20="timestamp","now()",IF(LEFT(AH20,9)="character","' '","0")),"") -> ' ' | AH20: =VLOOKUP(D20,カラムID辞書!C:H,3,FALSE) -> character varying | AM20: =VLOOKUP(D20,カラムID辞書!C:H,4,FALSE) -> 13 | AO20: =VLOOKUP(D20,カラムID辞書!C:H,6,FALSE) -> 13 | AQ20: 売上、仕入伝票の単品コード１ | BR20: （未設定）
B21: =IF($D21="","",MAX(OFFSET($B$8,0,0,ROW()-ROW($B$8),2))+1) -> 14 | D21: 単品コード２ | L21: =VLOOKUP(D21,カラムID辞書!$C$4:$D$1266,2,FALSE) -> TNPNCD2 | T21: 14 | AB21: =IF(L21="DELDTE","","○") -> ○ | AE21: =IF(AB21="○",IF(AH21="timestamp","now()",IF(LEFT(AH21,9)="character","' '","0")),"") -> ' ' | AH21: =VLOOKUP(D21,カラムID辞書!C:H,3,FALSE) -> character varying | AM21: =VLOOKUP(D21,カラムID辞書!C:H,4,FALSE) -> 13 | AO21: =VLOOKUP(D21,カラムID辞書!C:H,6,FALSE) -> 13 | AQ21: 売上、仕入伝票の単品コード２ | BR21: （未設定）
B22: =IF($D22="","",MAX(OFFSET($B$8,0,0,ROW()-ROW($B$8),2))+1) -> 15 | D22: 仕入区分 | L22: =VLOOKUP(D22,カラムID辞書!$C$4:$D$1266,2,FALSE) -> SHIIREKBN | T22: 15 | AB22: =IF(L22="DELDTE","","○") -> ○ | AE22: =IF(AB22="○",IF(AH22="timestamp","now()",IF(LEFT(AH22,9)="character","' '","0")),"") -> ' ' | AH22: =VLOOKUP(D22,カラムID辞書!C:H,3,FALSE) -> character varying | AM22: =VLOOKUP(D22,カラムID辞書!C:H,4,FALSE) -> 2 | AO22: =VLOOKUP(D22,カラムID辞書!C:H,6,FALSE) -> 2 | AQ22: 01：直扱 / 04：売仕
B23: =IF($D23="","",MAX(OFFSET($B$8,0,0,ROW()-ROW($B$8),2))+1) -> 16 | D23: 原価管理区分 | L23: =VLOOKUP(D23,カラムID辞書!$C$4:$D$1266,2,FALSE) -> GNKKBN | T23: 16 | AB23: =IF(L23="DELDTE","","○") -> ○ | AE23: =IF(AB23="○",IF(AH23="timestamp","now()",IF(LEFT(AH23,9)="character","' '","0")),"") -> ' ' | AH23: =VLOOKUP(D23,カラムID辞書!C:H,3,FALSE) -> character varying | AM23: =VLOOKUP(D23,カラムID辞書!C:H,4,FALSE) -> 1 | AO23: =VLOOKUP(D23,カラムID辞書!C:H,6,FALSE) -> 1 | AQ23: 1：売価品 / 2：原価品
B24: =IF($D24="","",MAX(OFFSET($B$8,0,0,ROW()-ROW($B$8),2))+1) -> 17 | D24: ＤＳ区分 | L24: =VLOOKUP(D24,カラムID辞書!$C$4:$D$1266,2,FALSE) -> DSKBN | T24: 17 | AB24: =IF(L24="DELDTE","","○") -> ○ | AE24: =IF(AB24="○",IF(AH24="timestamp","now()",IF(LEFT(AH24,9)="character","' '","0")),"") -> ' ' | AH24: =VLOOKUP(D24,カラムID辞書!C:H,3,FALSE) -> character varying | AM24: =VLOOKUP(D24,カラムID辞書!C:H,4,FALSE) -> 1 | AO24: =VLOOKUP(D24,カラムID辞書!C:H,6,FALSE) -> 1 | AQ24: 0：プロパー / 1：セール
B25: =IF($D25="","",MAX(OFFSET($B$8,0,0,ROW()-ROW($B$8),2))+1) -> 18 | D25: 利益計算式区分 | L25: =VLOOKUP(D25,カラムID辞書!$C$4:$D$1266,2,FALSE) -> RIEKICMPKBN | T25: 18 | AB25: =IF(L25="DELDTE","","○") -> ○ | AE25: =IF(AB25="○",IF(AH25="timestamp","now()",IF(LEFT(AH25,9)="character","' '","0")),"") -> ' ' | AH25: =VLOOKUP(D25,カラムID辞書!C:H,3,FALSE) -> character varying | AM25: =VLOOKUP(D25,カラムID辞書!C:H,4,FALSE) -> 1 | AO25: =VLOOKUP(D25,カラムID辞書!C:H,6,FALSE) -> 1 | AQ25: 0：利益計算対象外 / 1：売価還元原価法 / 3：売仕原価計算 /7：原価品計算
B26: =IF($D26="","",MAX(OFFSET($B$8,0,0,ROW()-ROW($B$8),2))+1) -> 19 | D26: 年月 | L26: =VLOOKUP(D26,カラムID辞書!$C$4:$D$1266,2,FALSE) -> YM | AB26: =IF(L26="DELDTE","","○") -> ○ | AE26: =IF(AB26="○",IF(AH26="timestamp","now()",IF(LEFT(AH26,9)="character","' '","0")),"") -> 0 | AH26: =VLOOKUP(D26,カラムID辞書!C:H,3,FALSE) -> numeric | AM26: =VLOOKUP(D26,カラムID辞書!C:H,4,FALSE) -> 6 | AO26: =VLOOKUP(D26,カラムID辞書!C:H,6,FALSE) -> 6 | AQ26: 「年月日」に該当する年月
B27: =IF($D27="","",MAX(OFFSET($B$8,0,0,ROW()-ROW($B$8),2))+1) -> 20 | D27: 期 | L27: =VLOOKUP(D27,カラムID辞書!$C$4:$D$1266,2,FALSE) -> NENKI | AB27: =IF(L27="DELDTE","","○") -> ○ | AE27: =IF(AB27="○",IF(AH27="timestamp","now()",IF(LEFT(AH27,9)="character","' '","0")),"") -> 0 | AH27: =VLOOKUP(D27,カラムID辞書!C:H,3,FALSE) -> numeric | AM27: =VLOOKUP(D27,カラムID辞書!C:H,4,FALSE) -> 6 | AO27: =VLOOKUP(D27,カラムID辞書!C:H,6,FALSE) -> 6 | AQ27: 「年月日」に該当する期首月（YYYYMM）
B28: =IF($D28="","",MAX(OFFSET($B$8,0,0,ROW()-ROW($B$8),2))+1) -> 21 | D28: 年 | L28: =VLOOKUP(D28,カラムID辞書!$C$4:$D$1266,2,FALSE) -> NENDO | AB28: =IF(L28="DELDTE","","○") -> ○ | AE28: =IF(AB28="○",IF(AH28="timestamp","now()",IF(LEFT(AH28,9)="character","' '","0")),"") -> 0 | AH28: =VLOOKUP(D28,カラムID辞書!C:H,3,FALSE) -> numeric | AM28: =VLOOKUP(D28,カラムID辞書!C:H,4,FALSE) -> 6 | AO28: =VLOOKUP(D28,カラムID辞書!C:H,6,FALSE) -> 6 | AQ28: 「年月日」に該当する年度開始月（YYYYMM）
B29: =IF($D29="","",MAX(OFFSET($B$8,0,0,ROW()-ROW($B$8),2))+1) -> 22 | D29: 売上高原価 | L29: =VLOOKUP(D29,カラムID辞書!$C$4:$D$1266,2,FALSE) -> URIAGED_GNK | AB29: =IF(L29="DELDTE","","○") -> ○ | AE29: =IF(AB29="○",IF(AH29="timestamp","now()",IF(LEFT(AH29,9)="character","' '","0")),"") -> 0 | AH29: =VLOOKUP(D29,カラムID辞書!C:H,3,FALSE) -> numeric | AM29: =VLOOKUP(D29,カラムID辞書!C:H,4,FALSE) -> 13 | AO29: =VLOOKUP(D29,カラムID辞書!C:H,6,FALSE) -> 13 | AQ29: 別紙「商品勘定利益計算」参照
B30: =IF($D30="","",MAX(OFFSET($B$8,0,0,ROW()-ROW($B$8),2))+1) -> 23 | D30: 売上高売価 | L30: =VLOOKUP(D30,カラムID辞書!$C$4:$D$1266,2,FALSE) -> URIAGED_BIK | AB30: =IF(L30="DELDTE","","○") -> ○ | AE30: =IF(AB30="○",IF(AH30="timestamp","now()",IF(LEFT(AH30,9)="character","' '","0")),"") -> 0 | AH30: =VLOOKUP(D30,カラムID辞書!C:H,3,FALSE) -> numeric | AM30: =VLOOKUP(D30,カラムID辞書!C:H,4,FALSE) -> 13 | AO30: =VLOOKUP(D30,カラムID辞書!C:H,6,FALSE) -> 13 | AQ30: 売上伝票の売上高集計値（総売上高）
B31: =IF($D31="","",MAX(OFFSET($B$8,0,0,ROW()-ROW($B$8),2))+1) -> 24 | D31: 売上高分類１ | L31: =VLOOKUP(D31,カラムID辞書!$C$4:$D$1266,2,FALSE) -> URIAGED_BNRI1 | AB31: =IF(L31="DELDTE","","○") -> ○ | AE31: =IF(AB31="○",IF(AH31="timestamp","now()",IF(LEFT(AH31,9)="character","' '","0")),"") -> 0 | AH31: =VLOOKUP(D31,カラムID辞書!C:H,3,FALSE) -> numeric | AM31: =VLOOKUP(D31,カラムID辞書!C:H,4,FALSE) -> 13 | AO31: =VLOOKUP(D31,カラムID辞書!C:H,6,FALSE) -> 13 | AQ31: 売上伝票の売上高集計値（店頭・普通品）
B32: =IF($D32="","",MAX(OFFSET($B$8,0,0,ROW()-ROW($B$8),2))+1) -> 25 | D32: 売上高分類２ | L32: =VLOOKUP(D32,カラムID辞書!$C$4:$D$1266,2,FALSE) -> URIAGED_BNRI2 | AB32: =IF(L32="DELDTE","","○") -> ○ | AE32: =IF(AB32="○",IF(AH32="timestamp","now()",IF(LEFT(AH32,9)="character","' '","0")),"") -> 0 | AH32: =VLOOKUP(D32,カラムID辞書!C:H,3,FALSE) -> numeric | AM32: =VLOOKUP(D32,カラムID辞書!C:H,4,FALSE) -> 13 | AO32: =VLOOKUP(D32,カラムID辞書!C:H,6,FALSE) -> 13 | AQ32: 売上伝票の売上高集計値（店頭・催事）
B33: =IF($D33="","",MAX(OFFSET($B$8,0,0,ROW()-ROW($B$8),2))+1) -> 26 | D33: 売上高分類３ | L33: =VLOOKUP(D33,カラムID辞書!$C$4:$D$1266,2,FALSE) -> URIAGED_BNRI3 | AB33: =IF(L33="DELDTE","","○") -> ○ | AE33: =IF(AB33="○",IF(AH33="timestamp","now()",IF(LEFT(AH33,9)="character","' '","0")),"") -> 0 | AH33: =VLOOKUP(D33,カラムID辞書!C:H,3,FALSE) -> numeric | AM33: =VLOOKUP(D33,カラムID辞書!C:H,4,FALSE) -> 13 | AO33: =VLOOKUP(D33,カラムID辞書!C:H,6,FALSE) -> 13 | AQ33: 売上伝票の売上高集計値（店頭・店外）
B34: =IF($D34="","",MAX(OFFSET($B$8,0,0,ROW()-ROW($B$8),2))+1) -> 27 | D34: 売上高分類４ | L34: =VLOOKUP(D34,カラムID辞書!$C$4:$D$1266,2,FALSE) -> URIAGED_BNRI4 | AB34: =IF(L34="DELDTE","","○") -> ○ | AE34: =IF(AB34="○",IF(AH34="timestamp","now()",IF(LEFT(AH34,9)="character","' '","0")),"") -> 0 | AH34: =VLOOKUP(D34,カラムID辞書!C:H,3,FALSE) -> numeric | AM34: =VLOOKUP(D34,カラムID辞書!C:H,4,FALSE) -> 13 | AO34: =VLOOKUP(D34,カラムID辞書!C:H,6,FALSE) -> 13 | AQ34: 売上伝票の売上高集計値（店頭・ギフト）
B35: =IF($D35="","",MAX(OFFSET($B$8,0,0,ROW()-ROW($B$8),2))+1) -> 28 | D35: 売上高分類５ | L35: =VLOOKUP(D35,カラムID辞書!$C$4:$D$1266,2,FALSE) -> URIAGED_BNRI5 | AB35: =IF(L35="DELDTE","","○") -> ○ | AE35: =IF(AB35="○",IF(AH35="timestamp","now()",IF(LEFT(AH35,9)="character","' '","0")),"") -> 0 | AH35: =VLOOKUP(D35,カラムID辞書!C:H,3,FALSE) -> numeric | AM35: =VLOOKUP(D35,カラムID辞書!C:H,4,FALSE) -> 13 | AO35: =VLOOKUP(D35,カラムID辞書!C:H,6,FALSE) -> 13 | AQ35: 売上伝票の売上高集計値（店頭・ネット）
B36: =IF($D36="","",MAX(OFFSET($B$8,0,0,ROW()-ROW($B$8),2))+1) -> 29 | D36: 売上高分類６ | L36: =VLOOKUP(D36,カラムID辞書!$C$4:$D$1266,2,FALSE) -> URIAGED_BNRI6 | AB36: =IF(L36="DELDTE","","○") -> ○ | AE36: =IF(AB36="○",IF(AH36="timestamp","now()",IF(LEFT(AH36,9)="character","' '","0")),"") -> 0 | AH36: =VLOOKUP(D36,カラムID辞書!C:H,3,FALSE) -> numeric | AM36: =VLOOKUP(D36,カラムID辞書!C:H,4,FALSE) -> 13 | AO36: =VLOOKUP(D36,カラムID辞書!C:H,6,FALSE) -> 13 | AQ36: 売上伝票の売上高集計値（店頭・その他）
B37: =IF($D37="","",MAX(OFFSET($B$8,0,0,ROW()-ROW($B$8),2))+1) -> 30 | D37: 売上高分類７ | L37: =VLOOKUP(D37,カラムID辞書!$C$4:$D$1266,2,FALSE) -> URIAGED_BNRI7 | AB37: =IF(L37="DELDTE","","○") -> ○ | AE37: =IF(AB37="○",IF(AH37="timestamp","now()",IF(LEFT(AH37,9)="character","' '","0")),"") -> 0 | AH37: =VLOOKUP(D37,カラムID辞書!C:H,3,FALSE) -> numeric | AM37: =VLOOKUP(D37,カラムID辞書!C:H,4,FALSE) -> 13 | AO37: =VLOOKUP(D37,カラムID辞書!C:H,6,FALSE) -> 13 | AQ37: 売上伝票の売上高集計値（非店頭・店外）
... B39: =IF($D39="","",MAX(OFFSET($B$8,0,0,ROW()-ROW($B$8),2))+1) -> 32 | D39: 売上高分類９ | L39: =VLOOKUP(D39,カラムID辞書!$C$4:$D$1266,2,FALSE) -> URIAGED_BNRI9 | AB39: =IF(L39="DELDTE","","○") -> ○ | AE39: =IF(AB39="○",IF(AH39="timestamp","now()",IF(LEFT(AH39,9)="character","' '","0")),"") -> 0 | AH39: =VLOOKUP(D39,カラムID辞書!C:H,3,FALSE) -> numeric | AM39: =VLOOKUP(D39,カラムID辞書!C:H,4,FALSE) -> 13 | AO39: =VLOOKUP(D39,カラムID辞書!C:H,6,FALSE) -> 13 | AQ39: 売上伝票の売上高集計値（非店頭・その他）
B40: =IF($D40="","",MAX(OFFSET($B$8,0,0,ROW()-ROW($B$8),2))+1) -> 33 | D40: 売上高分類１０ | L40: =VLOOKUP(D40,カラムID辞書!$C$4:$D$1266,2,FALSE) -> URIAGED_BNRI10 | AB40: =IF(L40="DELDTE","","○") -> ○ | AE40: =IF(AB40="○",IF(AH40="timestamp","now()",IF(LEFT(AH40,9)="character","' '","0")),"") -> 0 | AH40: =VLOOKUP(D40,カラムID辞書!C:H,3,FALSE) -> numeric | AM40: =VLOOKUP(D40,カラムID辞書!C:H,4,FALSE) -> 13 | AO40: =VLOOKUP(D40,カラムID辞書!C:H,6,FALSE) -> 13 | BR40: （未設定：ZERO）
B41: =IF($D41="","",MAX(OFFSET($B$8,0,0,ROW()-ROW($B$8),2))+1) -> 34 | D41: 売上高数量 | L41: =VLOOKUP(D41,カラムID辞書!$C$4:$D$1266,2,FALSE) -> URIAGED_SU | AB41: =IF(L41="DELDTE","","○") -> ○ | AE41: =IF(AB41="○",IF(AH41="timestamp","now()",IF(LEFT(AH41,9)="character","' '","0")),"") -> 0 | AH41: =VLOOKUP(D41,カラムID辞書!C:H,3,FALSE) -> numeric | AM41: =VLOOKUP(D41,カラムID辞書!C:H,4,FALSE) -> 10 | AO41: =VLOOKUP(D41,カラムID辞書!C:H,6,FALSE) -> 10 | AQ41: 売上伝票の売上数量集計値
B42: =IF($D42="","",MAX(OFFSET($B$8,0,0,ROW()-ROW($B$8),2))+1) -> 35 | D42: 利益高 | L42: =VLOOKUP(D42,カラムID辞書!$C$4:$D$1266,2,FALSE) -> RIEKID | AB42: =IF(L42="DELDTE","","○") -> ○ | AE42: =IF(AB42="○",IF(AH42="timestamp","now()",IF(LEFT(AH42,9)="character","' '","0")),"") -> 0 | AH42: =VLOOKUP(D42,カラムID辞書!C:H,3,FALSE) -> numeric | AM42: =VLOOKUP(D42,カラムID辞書!C:H,4,FALSE) -> 13 | AO42: =VLOOKUP(D42,カラムID辞書!C:H,6,FALSE) -> 13 | AQ42: 別紙「商品勘定利益計算」参照 | BR42: 売益金
B43: =IF($D43="","",MAX(OFFSET($B$8,0,0,ROW()-ROW($B$8),2))+1) -> 36 | D43: 割引額 | L43: =VLOOKUP(D43,カラムID辞書!$C$4:$D$1266,2,FALSE) -> WARIBIKI_GAK | AB43: =IF(L43="DELDTE","","○") -> ○ | AE43: =IF(AB43="○",IF(AH43="timestamp","now()",IF(LEFT(AH43,9)="character","' '","0")),"") -> 0 | AH43: =VLOOKUP(D43,カラムID辞書!C:H,3,FALSE) -> numeric | AM43: =VLOOKUP(D43,カラムID辞書!C:H,4,FALSE) -> 13 | AO43: =VLOOKUP(D43,カラムID辞書!C:H,6,FALSE) -> 13 | AQ43: 売上伝票の割引額集計値
B44: =IF($D44="","",MAX(OFFSET($B$8,0,0,ROW()-ROW($B$8),2))+1) -> 37 | D44: 値引額 | L44: =VLOOKUP(D44,カラムID辞書!$C$4:$D$1266,2,FALSE) -> NEBIKI_GAK | AB44: =IF(L44="DELDTE","","○") -> ○ | AE44: =IF(AB44="○",IF(AH44="timestamp","now()",IF(LEFT(AH44,9)="character","' '","0")),"") -> 0 | AH44: =VLOOKUP(D44,カラムID辞書!C:H,3,FALSE) -> numeric | AM44: =VLOOKUP(D44,カラムID辞書!C:H,4,FALSE) -> 13 | AO44: =VLOOKUP(D44,カラムID辞書!C:H,6,FALSE) -> 13 | AQ44: 売上伝票の値引額集計値
...

Sheet 売価還元単位別月別実績
B2: ユーザインタフェース 設計書 | J2: サブシステム分類 | O2: ドキュメント ID | T2: ドキュメント名 | BK2: 更新者 | BN2: 最終更新日 | BR2: 履歴 | BT2: 作成者 | BW2: 作成日
J3: 商品勘定 | O3: 2.04 | T3: テーブル定義 | BR3: 第1版 | BT3: 富士通 | BW3: 42917
B5: 概念データ名／ID | J5: 売価還元単位別月別実績テーブル | U5: ／ | V5: LBT02_BAIKAN_M | AD5: OID | AK5: 最大レコード長 | AR5: =ROUNDUP((27+ROUNDUP((MAX(B:B)-COUNTIF(AB:AB,"○"))/8,0)+IF(AF5="",0,4))/8,0)*8+SUM(AO8:AO1043) -> 1900 | AU5: Byte | AW5: 用途 | BB5: 商品勘定実績を月単位で管理する。
B7: 項番 | D7: 項目論理名称 | L7: 項目物理名称 | T7: PKey | V7: IDX1 | X7: IDX2 | Z7: IDX3 | AB7: NOTNULL | AE7: DEFAULT | AH7: Type | AM7: 桁数 | AO7: Byte | AQ7: 項目説明 | BR7: 備考
B8: 1 | D8: 年月 | L8: =VLOOKUP(D8,カラムID辞書!$C$4:$D$1266,2,FALSE) -> YM | T8: 1 | AB8: =IF(L8="DELDTE","","○") -> ○ | AE8: =IF(AB8="○",IF(AH8="timestamp","now()",IF(LEFT(AH8,9)="character","' '","0")),"") -> 0 | AH8: =VLOOKUP(D8,カラムID辞書!C:H,3,FALSE) -> numeric | AM8: =VLOOKUP(D8,カラムID辞書!C:H,4,FALSE) -> 6 | AO8: =VLOOKUP(D8,カラムID辞書!C:H,6,FALSE) -> 6 | AQ8: 伝票計上月
B9: =IF($D9="","",MAX(OFFSET($B$8,0,0,ROW()-ROW($B$8),2))+1) -> 2 | D9: システムグループコード | L9: =VLOOKUP(D9,カラムID辞書!$C$4:$D$1266,2,FALSE) -> SYSGRPCD | T9: 2 | AB9: =IF(L9="DELDTE","","○") -> ○ | AE9: =IF(AB9="○",IF(AH9="timestamp","now()",IF(LEFT(AH9,9)="character","' '","0")),"") -> ' ' | AH9: =VLOOKUP(D9,カラムID辞書!C:H,3,FALSE) -> character varying | AM9: =VLOOKUP(D9,カラムID辞書!C:H,4,FALSE) -> 4 | AO9: =VLOOKUP(D9,カラムID辞書!C:H,6,FALSE) -> 4 | AQ9: ユーザ分類コード | BR9: "0010"固定
B10: =IF($D10="","",MAX(OFFSET($B$8,0,0,ROW()-ROW($B$8),2))+1) -> 3 | D10: 企業グループコード | L10: =VLOOKUP(D10,カラムID辞書!$C$4:$D$1266,2,FALSE) -> KGYGRPCD | T10: 3 | AB10: =IF(L10="DELDTE","","○") -> ○ | AE10: =IF(AB10="○",IF(AH10="timestamp","now()",IF(LEFT(AH10,9)="character","' '","0")),"") -> ' ' | AH10: =VLOOKUP(D10,カラムID辞書!C:H,3,FALSE) -> character varying | AM10: =VLOOKUP(D10,カラムID辞書!C:H,4,FALSE) -> 3 | AO10: =VLOOKUP(D10,カラムID辞書!C:H,6,FALSE) -> 3 | AQ10: 売上、仕入伝票の企業グループコード
B11: =IF($D11="","",MAX(OFFSET($B$8,0,0,ROW()-ROW($B$8),2))+1) -> 4 | D11: 店コード | L11: =VLOOKUP(D11,カラムID辞書!$C$4:$D$1266,2,FALSE) -> TENCD | T11: 4 | AB11: =IF(L11="DELDTE","","○") -> ○ | AE11: =IF(AB11="○",IF(AH11="timestamp","now()",IF(LEFT(AH11,9)="character","' '","0")),"") -> ' ' | AH11: =VLOOKUP(D11,カラムID辞書!C:H,3,FALSE) -> character varying | AM11: =VLOOKUP(D11,カラムID辞書!C:H,4,FALSE) -> 4 | AO11: =VLOOKUP(D11,カラムID辞書!C:H,6,FALSE) -> 4 | AQ11: 売上、仕入伝票の店コード
B12: =IF($D12="","",MAX(OFFSET($B$8,0,0,ROW()-ROW($B$8),2))+1) -> 5 | D12: 商品コード１ | L12: =VLOOKUP(D12,カラムID辞書!$C$4:$D$1266,2,FALSE) -> SHOHINCD1 | T12: 5 | AB12: =IF(L12="DELDTE","","○") -> ○ | AE12: =IF(AB12="○",IF(AH12="timestamp","now()",IF(LEFT(AH12,9)="character","' '","0")),"") -> ' ' | AH12: =VLOOKUP(D12,カラムID辞書!C:H,3,FALSE) -> character varying | AM12: =VLOOKUP(D12,カラムID辞書!C:H,4,FALSE) -> 6 | AO12: =VLOOKUP(D12,カラムID辞書!C:H,6,FALSE) -> 6 | AQ12: 売上、仕入伝票の商品コード１ | BR12: 品番
B13: =IF($D13="","",MAX(OFFSET($B$8,0,0,ROW()-ROW($B$8),2))+1) -> 6 | D13: 商品コード２ | L13: =VLOOKUP(D13,カラムID辞書!$C$4:$D$1266,2,FALSE) -> SHOHINCD2 | T13: 6 | AB13: =IF(L13="DELDTE","","○") -> ○ | AE13: =IF(AB13="○",IF(AH13="timestamp","now()",IF(LEFT(AH13,9)="character","' '","0")),"") -> ' ' | AH13: =VLOOKUP(D13,カラムID辞書!C:H,3,FALSE) -> character varying | AM13: =VLOOKUP(D13,カラムID辞書!C:H,4,FALSE) -> 6 | AO13: =VLOOKUP(D13,カラムID辞書!C:H,6,FALSE) -> 6 | AQ13: 売上、仕入伝票の商品コード２ | BR13: （未設定）
B14: =IF($D14="","",MAX(OFFSET($B$8,0,0,ROW()-ROW($B$8),2))+1) -> 7 | D14: 商品コード３ | L14: =VLOOKUP(D14,カラムID辞書!$C$4:$D$1266,2,FALSE) -> SHOHINCD3 | T14: 7 | AB14: =IF(L14="DELDTE","","○") -> ○ | AE14: =IF(AB14="○",IF(AH14="timestamp","now()",IF(LEFT(AH14,9)="character","' '","0")),"") -> ' ' | AH14: =VLOOKUP(D14,カラムID辞書!C:H,3,FALSE) -> character varying | AM14: =VLOOKUP(D14,カラムID辞書!C:H,4,FALSE) -> 6 | AO14: =VLOOKUP(D14,カラムID辞書!C:H,6,FALSE) -> 6 | AQ14: 売上、仕入伝票の商品コード３ | BR14: （未設定）
B15: =IF($D15="","",MAX(OFFSET($B$8,0,0,ROW()-ROW($B$8),2))+1) -> 8 | D15: 商品コード４ | L15: =VLOOKUP(D15,カラムID辞書!$C$4:$D$1266,2,FALSE) -> SHOHINCD4 | T15: 8 | AB15: =IF(L15="DELDTE","","○") -> ○ | AE15: =IF(AB15="○",IF(AH15="timestamp","now()",IF(LEFT(AH15,9)="character","' '","0")),"") -> ' ' | AH15: =VLOOKUP(D15,カラムID辞書!C:H,3,FALSE) -> character varying | AM15: =VLOOKUP(D15,カラムID辞書!C:H,4,FALSE) -> 6 | AO15: =VLOOKUP(D15,カラムID辞書!C:H,6,FALSE) -> 6 | AQ15: 売上、仕入伝票の商品コード４ | BR15: （未設定）
B16: =IF($D16="","",MAX(OFFSET($B$8,0,0,ROW()-ROW($B$8),2))+1) -> 9 | D16: 商品コード５ | L16: =VLOOKUP(D16,カラムID辞書!$C$4:$D$1266,2,FALSE) -> SHOHINCD5 | T16: 9 | AB16: =IF(L16="DELDTE","","○") -> ○ | AE16: =IF(AB16="○",IF(AH16="timestamp","now()",IF(LEFT(AH16,9)="character","' '","0")),"") -> ' ' | AH16: =VLOOKUP(D16,カラムID辞書!C:H,3,FALSE) -> character varying | AM16: =VLOOKUP(D16,カラムID辞書!C:H,4,FALSE) -> 6 | AO16: =VLOOKUP(D16,カラムID辞書!C:H,6,FALSE) -> 6 | AQ16: 売上、仕入伝票の商品コード５ | BR16: （未設定）
B17: =IF($D17="","",MAX(OFFSET($B$8,0,0,ROW()-ROW($B$8),2))+1) -> 10 | D17: 細別コード１ | L17: =VLOOKUP(D17,カラムID辞書!$C$4:$D$1266,2,FALSE) -> SIBTCD1 | T17: 10 | AB17: =IF(L17="DELDTE","","○") -> ○ | AE17: =IF(AB17="○",IF(AH17="timestamp","now()",IF(LEFT(AH17,9)="character","' '","0")),"") -> ' ' | AH17: =VLOOKUP(D17,カラムID辞書!C:H,3,FALSE) -> character varying | AM17: =VLOOKUP(D17,カラムID辞書!C:H,4,FALSE) -> 10 | AO17: =VLOOKUP(D17,カラムID辞書!C:H,6,FALSE) -> 10 | AQ17: 売上、仕入伝票の細別コード１ | BR17: （未設定）
B18: =IF($D18="","",MAX(OFFSET($B$8,0,0,ROW()-ROW($B$8),2))+1) -> 11 | D18: 細別コード２ | L18: =VLOOKUP(D18,カラムID辞書!$C$4:$D$1266,2,FALSE) -> SIBTCD2 | T18: 11 | AB18: =IF(L18="DELDTE","","○") -> ○ | AE18: =IF(AB18="○",IF(AH18="timestamp","now()",IF(LEFT(AH18,9)="character","' '","0")),"") -> ' ' | AH18: =VLOOKUP(D18,カラムID辞書!C:H,3,FALSE) -> character varying | AM18: =VLOOKUP(D18,カラムID辞書!C:H,4,FALSE) -> 10 | AO18: =VLOOKUP(D18,カラムID辞書!C:H,6,FALSE) -> 10 | AQ18: 売上、仕入伝票の細別コード２ | BR18: （未設定）
B19: =IF($D19="","",MAX(OFFSET($B$8,0,0,ROW()-ROW($B$8),2))+1) -> 12 | D19: 単品コード１ | L19: =VLOOKUP(D19,カラムID辞書!$C$4:$D$1266,2,FALSE) -> TNPNCD1 | T19: 12 | AB19: =IF(L19="DELDTE","","○") -> ○ | AE19: =IF(AB19="○",IF(AH19="timestamp","now()",IF(LEFT(AH19,9)="character","' '","0")),"") -> ' ' | AH19: =VLOOKUP(D19,カラムID辞書!C:H,3,FALSE) -> character varying | AM19: =VLOOKUP(D19,カラムID辞書!C:H,4,FALSE) -> 13 | AO19: =VLOOKUP(D19,カラムID辞書!C:H,6,FALSE) -> 13 | AQ19: 売上、仕入伝票の単品コード１ | BR19: （未設定）
B20: =IF($D20="","",MAX(OFFSET($B$8,0,0,ROW()-ROW($B$8),2))+1) -> 13 | D20: 単品コード２ | L20: =VLOOKUP(D20,カラムID辞書!$C$4:$D$1266,2,FALSE) -> TNPNCD2 | T20: 13 | AB20: =IF(L20="DELDTE","","○") -> ○ | AE20: =IF(AB20="○",IF(AH20="timestamp","now()",IF(LEFT(AH20,9)="character","' '","0")),"") -> ' ' | AH20: =VLOOKUP(D20,カラムID辞書!C:H,3,FALSE) -> character varying | AM20: =VLOOKUP(D20,カラムID辞書!C:H,4,FALSE) -> 13 | AO20: =VLOOKUP(D20,カラムID辞書!C:H,6,FALSE) -> 13 | AQ20: 売上、仕入伝票の単品コード２ | BR20: （未設定）
B21: =IF($D21="","",MAX(OFFSET($B$8,0,0,ROW()-ROW($B$8),2))+1) -> 14 | D21: 仕入区分 | L21: =VLOOKUP(D21,カラムID辞書!$C$4:$D$1266,2,FALSE) -> SHIIREKBN | T21: 14 | AB21: =IF(L21="DELDTE","","○") -> ○ | AE21: =IF(AB21="○",IF(AH21="timestamp","now()",IF(LEFT(AH21,9)="character","' '","0")),"") -> ' ' | AH21: =VLOOKUP(D21,カラムID辞書!C:H,3,FALSE) -> character varying | AM21: =VLOOKUP(D21,カラムID辞書!C:H,4,FALSE) -> 2 | AO21: =VLOOKUP(D21,カラムID辞書!C:H,6,FALSE) -> 2 | AQ21: 01：直扱 / 04：売仕
B22: =IF($D22="","",MAX(OFFSET($B$8,0,0,ROW()-ROW($B$8),2))+1) -> 15 | D22: 原価管理区分 | L22: =VLOOKUP(D22,カラムID辞書!$C$4:$D$1266,2,FALSE) -> GNKKBN | T22: 15 | AB22: =IF(L22="DELDTE","","○") -> ○ | AE22: =IF(AB22="○",IF(AH22="timestamp","now()",IF(LEFT(AH22,9)="character","' '","0")),"") -> ' ' | AH22: =VLOOKUP(D22,カラムID辞書!C:H,3,FALSE) -> character varying | AM22: =VLOOKUP(D22,カラムID辞書!C:H,4,FALSE) -> 1 | AO22: =VLOOKUP(D22,カラムID辞書!C:H,6,FALSE) -> 1 | AQ22: 1：売価品 / 2：原価品
B23: =IF($D23="","",MAX(OFFSET($B$8,0,0,ROW()-ROW($B$8),2))+1) -> 16 | D23: ＤＳ区分 | L23: =VLOOKUP(D23,カラムID辞書!$C$4:$D$1266,2,FALSE) -> DSKBN | T23: 16 | AB23: =IF(L23="DELDTE","","○") -> ○ | AE23: =IF(AB23="○",IF(AH23="timestamp","now()",IF(LEFT(AH23,9)="character","' '","0")),"") -> ' ' | AH23: =VLOOKUP(D23,カラムID辞書!C:H,3,FALSE) -> character varying | AM23: =VLOOKUP(D23,カラムID辞書!C:H,4,FALSE) -> 1 | AO23: =VLOOKUP(D23,カラムID辞書!C:H,6,FALSE) -> 1 | AQ23: 0：プロパー / 1：セール
B24: =IF($D24="","",MAX(OFFSET($B$8,0,0,ROW()-ROW($B$8),2))+1) -> 17 | D24: 利益計算式区分 | L24: =VLOOKUP(D24,カラムID辞書!$C$4:$D$1266,2,FALSE) -> RIEKICMPKBN | T24: 17 | AB24: =IF(L24="DELDTE","","○") -> ○ | AE24: =IF(AB24="○",IF(AH24="timestamp","now()",IF(LEFT(AH24,9)="character","' '","0")),"") -> ' ' | AH24: =VLOOKUP(D24,カラムID辞書!C:H,3,FALSE) -> character varying | AM24: =VLOOKUP(D24,カラムID辞書!C:H,4,FALSE) -> 1 | AO24: =VLOOKUP(D24,カラムID辞書!C:H,6,FALSE) -> 1 | AQ24: 0：利益計算対象外 / 1：売価還元原価法 / 3：売仕原価計算 /7：原価品計算
B25: =IF($D25="","",MAX(OFFSET($B$8,0,0,ROW()-ROW($B$8),2))+1) -> 18 | D25: 期 | L25: =VLOOKUP(D25,カラムID辞書!$C$4:$D$1266,2,FALSE) -> NENKI | AB25: =IF(L25="DELDTE","","○") -> ○ | AE25: =IF(AB25="○",IF(AH25="timestamp","now()",IF(LEFT(AH25,9)="character","' '","0")),"") -> 0 | AH25: =VLOOKUP(D25,カラムID辞書!C:H,3,FALSE) -> numeric | AM25: =VLOOKUP(D25,カラムID辞書!C:H,4,FALSE) -> 6 | AO25: =VLOOKUP(D25,カラムID辞書!C:H,6,FALSE) -> 6 | AQ25: 「年月」に該当する期首月（YYYYMM）
B26: =IF($D26="","",MAX(OFFSET($B$8,0,0,ROW()-ROW($B$8),2))+1) -> 19 | D26: 年 | L26: =VLOOKUP(D26,カラムID辞書!$C$4:$D$1266,2,FALSE) -> NENDO | AB26: =IF(L26="DELDTE","","○") -> ○ | AE26: =IF(AB26="○",IF(AH26="timestamp","now()",IF(LEFT(AH26,9)="character","' '","0")),"") -> 0 | AH26: =VLOOKUP(D26,カラムID辞書!C:H,3,FALSE) -> numeric | AM26: =VLOOKUP(D26,カラムID辞書!C:H,4,FALSE) -> 6 | AO26: =VLOOKUP(D26,カラムID辞書!C:H,6,FALSE) -> 6 | AQ26: 「年月」に該当する年度開始月（YYYYMM）
B27: =IF($D27="","",MAX(OFFSET($B$8,0,0,ROW()-ROW($B$8),2))+1) -> 20 | D27: 売上高原価 | L27: =VLOOKUP(D27,カラムID辞書!$C$4:$D$1266,2,FALSE) -> URIAGED_GNK | AB27: =IF(L27="DELDTE","","○") -> ○ | AE27: =IF(AB27="○",IF(AH27="timestamp","now()",IF(LEFT(AH27,9)="character","' '","0")),"") -> 0 | AH27: =VLOOKUP(D27,カラムID辞書!C:H,3,FALSE) -> numeric | AM27: =VLOOKUP(D27,カラムID辞書!C:H,4,FALSE) -> 13 | AO27: =VLOOKUP(D27,カラムID辞書!C:H,6,FALSE) -> 13 | AQ27: 別紙「商品勘定利益計算」参照
B28: =IF($D28="","",MAX(OFFSET($B$8,0,0,ROW()-ROW($B$8),2))+1) -> 21 | D28: 売上高売価 | L28: =VLOOKUP(D28,カラムID辞書!$C$4:$D$1266,2,FALSE) -> URIAGED_BIK | AB28: =IF(L28="DELDTE","","○") -> ○ | AE28: =IF(AB28="○",IF(AH28="timestamp","now()",IF(LEFT(AH28,9)="character","' '","0")),"") -> 0 | AH28: =VLOOKUP(D28,カラムID辞書!C:H,3,FALSE) -> numeric | AM28: =VLOOKUP(D28,カラムID辞書!C:H,4,FALSE) -> 13 | AO28: =VLOOKUP(D28,カラムID辞書!C:H,6,FALSE) -> 13 | AQ28: 売上伝票の売上高集計値（総売上高）
B29: =IF($D29="","",MAX(OFFSET($B$8,0,0,ROW()-ROW($B$8),2))+1) -> 22 | D29: 売上高分類１ | L29: =VLOOKUP(D29,カラムID辞書!$C$4:$D$1266,2,FALSE) -> URIAGED_BNRI1 | AB29: =IF(L29="DELDTE","","○") -> ○ | AE29: =IF(AB29="○",IF(AH29="timestamp","now()",IF(LEFT(AH29,9)="character","' '","0")),"") -> 0 | AH29: =VLOOKUP(D29,カラムID辞書!C:H,3,FALSE) -> numeric | AM29: =VLOOKUP(D29,カラムID辞書!C:H,4,FALSE) -> 13 | AO29: =VLOOKUP(D29,カラムID辞書!C:H,6,FALSE) -> 13 | AQ29: 売上伝票の売上高集計値（店頭・普通品）
B30: =IF($D30="","",MAX(OFFSET($B$8,0,0,ROW()-ROW($B$8),2))+1) -> 23 | D30: 売上高分類２ | L30: =VLOOKUP(D30,カラムID辞書!$C$4:$D$1266,2,FALSE) -> URIAGED_BNRI2 | AB30: =IF(L30="DELDTE","","○") -> ○ | AE30: =IF(AB30="○",IF(AH30="timestamp","now()",IF(LEFT(AH30,9)="character","' '","0")),"") -> 0 | AH30: =VLOOKUP(D30,カラムID辞書!C:H,3,FALSE) -> numeric | AM30: =VLOOKUP(D30,カラムID辞書!C:H,4,FALSE) -> 13 | AO30: =VLOOKUP(D30,カラムID辞書!C:H,6,FALSE) -> 13 | AQ30: 売上伝票の売上高集計値（店頭・催事）
B31: =IF($D31="","",MAX(OFFSET($B$8,0,0,ROW()-ROW($B$8),2))+1) -> 24 | D31: 売上高分類３ | L31: =VLOOKUP(D31,カラムID辞書!$C$4:$D$1266,2,FALSE) -> URIAGED_BNRI3 | AB31: =IF(L31="DELDTE","","○") -> ○ | AE31: =IF(AB31="○",IF(AH31="timestamp","now()",IF(LEFT(AH31,9)="character","' '","0")),"") -> 0 | AH31: =VLOOKUP(D31,カラムID辞書!C:H,3,FALSE) -> numeric | AM31: =VLOOKUP(D31,カラムID辞書!C:H,4,FALSE) -> 13 | AO31: =VLOOKUP(D31,カラムID辞書!C:H,6,FALSE) -> 13 | AQ31: 売上伝票の売上高集計値（店頭・店外）
B32: =IF($D32="","",MAX(OFFSET($B$8,0,0,ROW()-ROW($B$8),2))+1) -> 25 | D32: 売上高分類４ | L32: =VLOOKUP(D32,カラムID辞書!$C$4:$D$1266,2,FALSE) -> URIAGED_BNRI4 | AB32: =IF(L32="DELDTE","","○") -> ○ | AE32: =IF(AB32="○",IF(AH32="timestamp","now()",IF(LEFT(AH32,9)="character","' '","0")),"") -> 0 | AH32: =VLOOKUP(D32,カラムID辞書!C:H,3,FALSE) -> numeric | AM32: =VLOOKUP(D32,カラムID辞書!C:H,4,FALSE) -> 13 | AO32: =VLOOKUP(D32,カラムID辞書!C:H,6,FALSE) -> 13 | AQ32: 売上伝票の売上高集計値（店頭・ギフト）
B33: =IF($D33="","",MAX(OFFSET($B$8,0,0,ROW()-ROW($B$8),2))+1) -> 26 | D33: 売上高分類５ | L33: =VLOOKUP(D33,カラムID辞書!$C$4:$D$1266,2,FALSE) -> URIAGED_BNRI5 | AB33: =IF(L33="DELDTE","","○") -> ○ | AE33: =IF(AB33="○",IF(AH33="timestamp","now()",IF(LEFT(AH33,9)="character","' '","0")),"") -> 0 | AH33: =VLOOKUP(D33,カラムID辞書!C:H,3,FALSE) -> numeric | AM33: =VLOOKUP(D33,カラムID辞書!C:H,4,FALSE) -> 13 | AO33: =VLOOKUP(D33,カラムID辞書!C:H,6,FALSE) -> 13 | AQ33: 売上伝票の売上高集計値（店頭・ネット）
B34: =IF($D34="","",MAX(OFFSET($B$8,0,0,ROW()-ROW($B$8),2))+1) -> 27 | D34: 売上高分類６ | L34: =VLOOKUP(D34,カラムID辞書!$C$4:$D$1266,2,FALSE) -> URIAGED_BNRI6 | AB34: =IF(L34="DELDTE","","○") -> ○ | AE34: =IF(AB34="○",IF(AH34="timestamp","now()",IF(LEFT(AH34,9)="character","' '","0")),"") -> 0 | AH34: =VLOOKUP(D34,カラムID辞書!C:H,3,FALSE) -> numeric | AM34: =VLOOKUP(D34,カラムID辞書!C:H,4,FALSE) -> 13 | AO34: =VLOOKUP(D34,カラムID辞書!C:H,6,FALSE) -> 13 | AQ34: 売上伝票の売上高集計値（店頭・その他）
B35: =IF($D35="","",MAX(OFFSET($B$8,0,0,ROW()-ROW($B$8),2))+1) -> 28 | D35: 売上高分類７ | L35: =VLOOKUP(D35,カラムID辞書!$C$4:$D$1266,2,FALSE) -> URIAGED_BNRI7 | AB35: =IF(L35="DELDTE","","○") -> ○ | AE35: =IF(AB35="○",IF(AH35="timestamp","now()",IF(LEFT(AH35,9)="character","' '","0")),"") -> 0 | AH35: =VLOOKUP(D35,カラムID辞書!C:H,3,FALSE) -> numeric | AM35: =VLOOKUP(D35,カラムID辞書!C:H,4,FALSE) -> 13 | AO35: =VLOOKUP(D35,カラムID辞書!C:H,6,FALSE) -> 13 | AQ35: 売上伝票の売上高集計値（非店頭・店外）
B36: =IF($D36="","",MAX(OFFSET($B$8,0,0,ROW()-ROW($B$8),2))+1) -> 29 | D36: 売上高分類８ | L36: =VLOOKUP(D36,カラムID辞書!$C$4:$D$1266,2,FALSE) -> URIAGED_BNRI8 | AB36: =IF(L36="DELDTE","","○") -> ○ | AE36: =IF(AB36="○",IF(AH36="timestamp","now()",IF(LEFT(AH36,9)="character","' '","0")),"") -> 0 | AH36: =VLOOKUP(D36,カラムID辞書!C:H,3,FALSE) -> numeric | AM36: =VLOOKUP(D36,カラムID辞書!C:H,4,FALSE) -> 13 | AO36: =VLOOKUP(D36,カラムID辞書!C:H,6,FALSE) -> 13 | AQ36: 売上伝票の売上高集計値（非店頭・ギフト）
B37: =IF($D37="","",MAX(OFFSET($B$8,0,0,ROW()-ROW($B$8),2))+1) -> 30 | D37: 売上高分類９ | L37: =VLOOKUP(D37,カラムID辞書!$C$4:$D$1266,2,FALSE) -> URIAGED_BNRI9 | AB37: =IF(L37="DELDTE","","○") -> ○ | AE37: =IF(AB37="○",IF(AH37="timestamp","now()",IF(LEFT(AH37,9)="character","' '","0")),"") -> 0 | AH37: =VLOOKUP(D37,カラムID辞書!C:H,3,FALSE) -> numeric | AM37: =VLOOKUP(D37,カラムID辞書!C:H,4,FALSE) -> 13 | AO37: =VLOOKUP(D37,カラムID辞書!C:H,6,FALSE) -> 13 | AQ37: 売上伝票の売上高集計値（非店頭・その他）
B38: =IF($D38="","",MAX(OFFSET($B$8,0,0,ROW()-ROW($B$8),2))+1) -> 31 | D38: 売上高分類１０ | L38: =VLOOKUP(D38,カラムID辞書!$C$4:$D$1266,2,FALSE) -> URIAGED_BNRI10 | AB38: =IF(L38="DELDTE","","○") -> ○ | AE38: =IF(AB38="○",IF(AH38="timestamp","now()",IF(LEFT(AH38,9)="character","' '","0")),"") -> 0 | AH38: =VLOOKUP(D38,カラムID辞書!C:H,3,FALSE) -> numeric | AM38: =VLOOKUP(D38,カラムID辞書!C:H,4,FALSE) -> 13 | AO38: =VLOOKUP(D38,カラムID辞書!C:H,6,FALSE) -> 13 | BR38: （未設定：ZERO）
B39: =IF($D39="","",MAX(OFFSET($B$8,0,0,ROW()-ROW($B$8),2))+1) -> 32 | D39: 売上高数量 | L39: =VLOOKUP(D39,カラムID辞書!$C$4:$D$1266,2,FALSE) -> URIAGED_SU | AB39: =IF(L39="DELDTE","","○") -> ○ | AE39: =IF(AB39="○",IF(AH39="timestamp","now()",IF(LEFT(AH39,9)="character","' '","0")),"") -> 0 | AH39: =VLOOKUP(D39,カラムID辞書!C:H,3,FALSE) -> numeric | AM39: =VLOOKUP(D39,カラムID辞書!C:H,4,FALSE) -> 10 | AO39: =VLOOKUP(D39,カラムID辞書!C:H,6,FALSE) -> 10 | AQ39: 売上伝票の売上数量集計値
B40: =IF($D40="","",MAX(OFFSET($B$8,0,0,ROW()-ROW($B$8),2))+1) -> 33 | D40: 利益高 | L40: =VLOOKUP(D40,カラムID辞書!$C$4:$D$1266,2,FALSE) -> RIEKID | AB40: =IF(L40="DELDTE","","○") -> ○ | AE40: =IF(AB40="○",IF(AH40="timestamp","now()",IF(LEFT(AH40,9)="character","' '","0")),"") -> 0 | AH40: =VLOOKUP(D40,カラムID辞書!C:H,3,FALSE) -> numeric | AM40: =VLOOKUP(D40,カラムID辞書!C:H,4,FALSE) -> 13 | AO40: =VLOOKUP(D40,カラムID辞書!C:H,6,FALSE) -> 13 | AQ40: 別紙「商品勘定利益計算」参照 | BR40: 売益金
B41: =IF($D41="","",MAX(OFFSET($B$8,0,0,ROW()-ROW($B$8),2))+1) -> 34 | D41: 割引額 | L41: =VLOOKUP(D41,カラムID辞書!$C$4:$D$1266,2,FALSE) -> WARIBIKI_GAK | AB41: =IF(L41="DELDTE","","○") -> ○ | AE41: =IF(AB41="○",IF(AH41="timestamp","now()",IF(LEFT(AH41,9)="character","' '","0")),"") -> 0 | AH41: =VLOOKUP(D41,カラムID辞書!C:H,3,FALSE) -> numeric | AM41: =VLOOKUP(D41,カラムID辞書!C:H,4,FALSE) -> 13 | AO41: =VLOOKUP(D41,カラムID辞書!C:H,6,FALSE) -> 13 | AQ41: 売上伝票の割引額集計値
B42: =IF($D42="","",MAX(OFFSET($B$8,0,0,ROW()-ROW($B$8),2))+1) -> 35 | D42: 値引額 | L42: =VLOOKUP(D42,カラムID辞書!$C$4:$D$1266,2,FALSE) -> NEBIKI_GAK | AB42: =IF(L42="DELDTE","","○") -> ○ | AE42: =IF(AB42="○",IF(AH42="timestamp","now()",IF(LEFT(AH42,9)="character","' '","0")),"") -> 0 | AH42: =VLOOKUP(D42,カラムID辞書!C:H,3,FALSE) -> numeric | AM42: =VLOOKUP(D42,カラムID辞書!C:H,4,FALSE) -> 13 | AO42: =VLOOKUP(D42,カラムID辞書!C:H,6,FALSE) -> 13 | AQ42: 売上伝票の値引額集計値
B43: =IF($D43="","",MAX(OFFSET($B$8,0,0,ROW()-ROW($B$8),2))+1) -> 36 | D43: 客数１ | L43: =VLOOKUP(D43,カラムID辞書!$C$4:$D$1266,2,FALSE) -> KYAKU1_SU | AB43: =IF(L43="DELDTE","","○") -> ○ | AE43: =IF(AB43="○",IF(AH43="timestamp","now()",IF(LEFT(AH43,9)="character","' '","0")),"") -> 0 | AH43: =VLOOKUP(D43,カラムID辞書!C:H,3,FALSE) -> numeric | AM43: =VLOOKUP(D43,カラムID辞書!C:H,4,FALSE) -> 10,2 | AO43: =VLOOKUP(D43,カラムID辞書!C:H,6,FALSE) -> 10 | AQ43: 売上伝票の客数１集計値
...

Sheet 売価還元単位別期別実績
B2: ユーザインタフェース 設計書 | J2: サブシステム分類 | O2: ドキュメント ID | T2: ドキュメント名 | BK2: 更新者 | BN2: 最終更新日 | BR2: 履歴 | BT2: 作成者 | BW2: 作成日
J3: 商品勘定 | O3: 2.04 | T3: テーブル定義 | BR3: 第1版 | BT3: 富士通 | BW3: 42917
B5: 概念データ名／ID | J5: 売価還元単位別期別実績テーブル | U5: ／ | V5: LBT03_BAIKAN_K | AD5: OID | AK5: 最大レコード長 | AR5: =ROUNDUP((27+ROUNDUP((MAX(B:B)-COUNTIF(AB:AB,"○"))/8,0)+IF(AF5="",0,4))/8,0)*8+SUM(AO8:AO1034) -> 1828 | AU5: Byte | AW5: 用途 | BB5: 商品勘定実績を期単位で管理する。
B7: 項番 | D7: 項目論理名称 | L7: 項目物理名称 | T7: PKey | V7: IDX1 | X7: IDX2 | Z7: IDX3 | AB7: NOTNULL | AE7: DEFAULT | AH7: Type | AM7: 桁数 | AO7: Byte | AQ7: 項目説明 | BR7: 備考
B8: 1 | D8: 期 | L8: =VLOOKUP(D8,カラムID辞書!$C$4:$D$1266,2,FALSE) -> NENKI | T8: 1 | AB8: =IF(L8="DELDTE","","○") -> ○ | AE8: =IF(AB8="○",IF(AH8="timestamp","now()",IF(LEFT(AH8,9)="character","' '","0")),"") -> 0 | AH8: =VLOOKUP(D8,カラムID辞書!C:H,3,FALSE) -> numeric | AM8: =VLOOKUP(D8,カラムID辞書!C:H,4,FALSE) -> 6 | AO8: =VLOOKUP(D8,カラムID辞書!C:H,6,FALSE) -> 6 | AQ8: 伝票計上日に該当する期首月（YYYYMM）
B9: =IF($D9="","",MAX(OFFSET($B$8,0,0,ROW()-ROW($B$8),2))+1) -> 2 | D9: システムグループコード | L9: =VLOOKUP(D9,カラムID辞書!$C$4:$D$1266,2,FALSE) -> SYSGRPCD | T9: 2 | AB9: =IF(L9="DELDTE","","○") -> ○ | AE9: =IF(AB9="○",IF(AH9="timestamp","now()",IF(LEFT(AH9,9)="character","' '","0")),"") -> ' ' | AH9: =VLOOKUP(D9,カラムID辞書!C:H,3,FALSE) -> character varying | AM9: =VLOOKUP(D9,カラムID辞書!C:H,4,FALSE) -> 4 | AO9: =VLOOKUP(D9,カラムID辞書!C:H,6,FALSE) -> 4 | AQ9: ユーザ分類コード | BR9: "0010"固定
B10: =IF($D10="","",MAX(OFFSET($B$8,0,0,ROW()-ROW($B$8),2))+1) -> 3 | D10: 企業グループコード | L10: =VLOOKUP(D10,カラムID辞書!$C$4:$D$1266,2,FALSE) -> KGYGRPCD | T10: 3 | AB10: =IF(L10="DELDTE","","○") -> ○ | AE10: =IF(AB10="○",IF(AH10="timestamp","now()",IF(LEFT(AH10,9)="character","' '","0")),"") -> ' ' | AH10: =VLOOKUP(D10,カラムID辞書!C:H,3,FALSE) -> character varying | AM10: =VLOOKUP(D10,カラムID辞書!C:H,4,FALSE) -> 3 | AO10: =VLOOKUP(D10,カラムID辞書!C:H,6,FALSE) -> 3 | AQ10: 売上、仕入伝票の企業グループコード
B11: =IF($D11="","",MAX(OFFSET($B$8,0,0,ROW()-ROW($B$8),2))+1) -> 4 | D11: 店コード | L11: =VLOOKUP(D11,カラムID辞書!$C$4:$D$1266,2,FALSE) -> TENCD | T11: 4 | AB11: =IF(L11="DELDTE","","○") -> ○ | AE11: =IF(AB11="○",IF(AH11="timestamp","now()",IF(LEFT(AH11,9)="character","' '","0")),"") -> ' ' | AH11: =VLOOKUP(D11,カラムID辞書!C:H,3,FALSE) -> character varying | AM11: =VLOOKUP(D11,カラムID辞書!C:H,4,FALSE) -> 4 | AO11: =VLOOKUP(D11,カラムID辞書!C:H,6,FALSE) -> 4 | AQ11: 売上、仕入伝票の店コード
B12: =IF($D12="","",MAX(OFFSET($B$8,0,0,ROW()-ROW($B$8),2))+1) -> 5 | D12: 商品コード１ | L12: =VLOOKUP(D12,カラムID辞書!$C$4:$D$1266,2,FALSE) -> SHOHINCD1 | T12: 5 | AB12: =IF(L12="DELDTE","","○") -> ○ | AE12: =IF(AB12="○",IF(AH12="timestamp","now()",IF(LEFT(AH12,9)="character","' '","0")),"") -> ' ' | AH12: =VLOOKUP(D12,カラムID辞書!C:H,3,FALSE) -> character varying | AM12: =VLOOKUP(D12,カラムID辞書!C:H,4,FALSE) -> 6 | AO12: =VLOOKUP(D12,カラムID辞書!C:H,6,FALSE) -> 6 | AQ12: 売上、仕入伝票の商品コード１ | BR12: 品番
B13: =IF($D13="","",MAX(OFFSET($B$8,0,0,ROW()-ROW($B$8),2))+1) -> 6 | D13: 商品コード２ | L13: =VLOOKUP(D13,カラムID辞書!$C$4:$D$1266,2,FALSE) -> SHOHINCD2 | T13: 6 | AB13: =IF(L13="DELDTE","","○") -> ○ | AE13: =IF(AB13="○",IF(AH13="timestamp","now()",IF(LEFT(AH13,9)="character","' '","0")),"") -> ' ' | AH13: =VLOOKUP(D13,カラムID辞書!C:H,3,FALSE) -> character varying | AM13: =VLOOKUP(D13,カラムID辞書!C:H,4,FALSE) -> 6 | AO13: =VLOOKUP(D13,カラムID辞書!C:H,6,FALSE) -> 6 | AQ13: 売上、仕入伝票の商品コード２ | BR13: （未設定）
B14: =IF($D14="","",MAX(OFFSET($B$8,0,0,ROW()-ROW($B$8),2))+1) -> 7 | D14: 商品コード３ | L14: =VLOOKUP(D14,カラムID辞書!$C$4:$D$1266,2,FALSE) -> SHOHINCD3 | T14: 7 | AB14: =IF(L14="DELDTE","","○") -> ○ | AE14: =IF(AB14="○",IF(AH14="timestamp","now()",IF(LEFT(AH14,9)="character","' '","0")),"") -> ' ' | AH14: =VLOOKUP(D14,カラムID辞書!C:H,3,FALSE) -> character varying | AM14: =VLOOKUP(D14,カラムID辞書!C:H,4,FALSE) -> 6 | AO14: =VLOOKUP(D14,カラムID辞書!C:H,6,FALSE) -> 6 | AQ14: 売上、仕入伝票の商品コード３ | BR14: （未設定）
B15: =IF($D15="","",MAX(OFFSET($B$8,0,0,ROW()-ROW($B$8),2))+1) -> 8 | D15: 商品コード４ | L15: =VLOOKUP(D15,カラムID辞書!$C$4:$D$1266,2,FALSE) -> SHOHINCD4 | T15: 8 | AB15: =IF(L15="DELDTE","","○") -> ○ | AE15: =IF(AB15="○",IF(AH15="timestamp","now()",IF(LEFT(AH15,9)="character","' '","0")),"") -> ' ' | AH15: =VLOOKUP(D15,カラムID辞書!C:H,3,FALSE) -> character varying | AM15: =VLOOKUP(D15,カラムID辞書!C:H,4,FALSE) -> 6 | AO15: =VLOOKUP(D15,カラムID辞書!C:H,6,FALSE) -> 6 | AQ15: 売上、仕入伝票の商品コード４ | BR15: （未設定）
B16: =IF($D16="","",MAX(OFFSET($B$8,0,0,ROW()-ROW($B$8),2))+1) -> 9 | D16: 商品コード５ | L16: =VLOOKUP(D16,カラムID辞書!$C$4:$D$1266,2,FALSE) -> SHOHINCD5 | T16: 9 | AB16: =IF(L16="DELDTE","","○") -> ○ | AE16: =IF(AB16="○",IF(AH16="timestamp","now()",IF(LEFT(AH16,9)="character","' '","0")),"") -> ' ' | AH16: =VLOOKUP(D16,カラムID辞書!C:H,3,FALSE) -> character varying | AM16: =VLOOKUP(D16,カラムID辞書!C:H,4,FALSE) -> 6 | AO16: =VLOOKUP(D16,カラムID辞書!C:H,6,FALSE) -> 6 | AQ16: 売上、仕入伝票の商品コード５ | BR16: （未設定）
B17: =IF($D17="","",MAX(OFFSET($B$8,0,0,ROW()-ROW($B$8),2))+1) -> 10 | D17: 細別コード１ | L17: =VLOOKUP(D17,カラムID辞書!$C$4:$D$1266,2,FALSE) -> SIBTCD1 | T17: 10 | AB17: =IF(L17="DELDTE","","○") -> ○ | AE17: =IF(AB17="○",IF(AH17="timestamp","now()",IF(LEFT(AH17,9)="character","' '","0")),"") -> ' ' | AH17: =VLOOKUP(D17,カラムID辞書!C:H,3,FALSE) -> character varying | AM17: =VLOOKUP(D17,カラムID辞書!C:H,4,FALSE) -> 10 | AO17: =VLOOKUP(D17,カラムID辞書!C:H,6,FALSE) -> 10 | AQ17: 売上、仕入伝票の細別コード１ | BR17: （未設定）
B18: =IF($D18="","",MAX(OFFSET($B$8,0,0,ROW()-ROW($B$8),2))+1) -> 11 | D18: 細別コード２ | L18: =VLOOKUP(D18,カラムID辞書!$C$4:$D$1266,2,FALSE) -> SIBTCD2 | T18: 11 | AB18: =IF(L18="DELDTE","","○") -> ○ | AE18: =IF(AB18="○",IF(AH18="timestamp","now()",IF(LEFT(AH18,9)="character","' '","0")),"") -> ' ' | AH18: =VLOOKUP(D18,カラムID辞書!C:H,3,FALSE) -> character varying | AM18: =VLOOKUP(D18,カラムID辞書!C:H,4,FALSE) -> 10 | AO18: =VLOOKUP(D18,カラムID辞書!C:H,6,FALSE) -> 10 | AQ18: 売上、仕入伝票の細別コード２ | BR18: （未設定）
B19: =IF($D19="","",MAX(OFFSET($B$8,0,0,ROW()-ROW($B$8),2))+1) -> 12 | D19: 単品コード１ | L19: =VLOOKUP(D19,カラムID辞書!$C$4:$D$1266,2,FALSE) -> TNPNCD1 | T19: 12 | AB19: =IF(L19="DELDTE","","○") -> ○ | AE19: =IF(AB19="○",IF(AH19="timestamp","now()",IF(LEFT(AH19,9)="character","' '","0")),"") -> ' ' | AH19: =VLOOKUP(D19,カラムID辞書!C:H,3,FALSE) -> character varying | AM19: =VLOOKUP(D19,カラムID辞書!C:H,4,FALSE) -> 13 | AO19: =VLOOKUP(D19,カラムID辞書!C:H,6,FALSE) -> 13 | AQ19: 売上、仕入伝票の単品コード１ | BR19: （未設定）
B20: =IF($D20="","",MAX(OFFSET($B$8,0,0,ROW()-ROW($B$8),2))+1) -> 13 | D20: 単品コード２ | L20: =VLOOKUP(D20,カラムID辞書!$C$4:$D$1266,2,FALSE) -> TNPNCD2 | T20: 13 | AB20: =IF(L20="DELDTE","","○") -> ○ | AE20: =IF(AB20="○",IF(AH20="timestamp","now()",IF(LEFT(AH20,9)="character","' '","0")),"") -> ' ' | AH20: =VLOOKUP(D20,カラムID辞書!C:H,3,FALSE) -> character varying | AM20: =VLOOKUP(D20,カラムID辞書!C:H,4,FALSE) -> 13 | AO20: =VLOOKUP(D20,カラムID辞書!C:H,6,FALSE) -> 13 | AQ20: 売上、仕入伝票の単品コード２ | BR20: （未設定）
B21: =IF($D21="","",MAX(OFFSET($B$8,0,0,ROW()-ROW($B$8),2))+1) -> 14 | D21: 仕入区分 | L21: =VLOOKUP(D21,カラムID辞書!$C$4:$D$1266,2,FALSE) -> SHIIREKBN | T21: 14 | AB21: =IF(L21="DELDTE","","○") -> ○ | AE21: =IF(AB21="○",IF(AH21="timestamp","now()",IF(LEFT(AH21,9)="character","' '","0")),"") -> ' ' | AH21: =VLOOKUP(D21,カラムID辞書!C:H,3,FALSE) -> character varying | AM21: =VLOOKUP(D21,カラムID辞書!C:H,4,FALSE) -> 2 | AO21: =VLOOKUP(D21,カラムID辞書!C:H,6,FALSE) -> 2 | AQ21: 01：直扱 / 04：売仕
B22: =IF($D22="","",MAX(OFFSET($B$8,0,0,ROW()-ROW($B$8),2))+1) -> 15 | D22: 原価管理区分 | L22: =VLOOKUP(D22,カラムID辞書!$C$4:$D$1266,2,FALSE) -> GNKKBN | T22: 15 | AB22: =IF(L22="DELDTE","","○") -> ○ | AE22: =IF(AB22="○",IF(AH22="timestamp","now()",IF(LEFT(AH22,9)="character","' '","0")),"") -> ' ' | AH22: =VLOOKUP(D22,カラムID辞書!C:H,3,FALSE) -> character varying | AM22: =VLOOKUP(D22,カラムID辞書!C:H,4,FALSE) -> 1 | AO22: =VLOOKUP(D22,カラムID辞書!C:H,6,FALSE) -> 1 | AQ22: 1：売価品 / 2：原価品
B23: =IF($D23="","",MAX(OFFSET($B$8,0,0,ROW()-ROW($B$8),2))+1) -> 16 | D23: ＤＳ区分 | L23: =VLOOKUP(D23,カラムID辞書!$C$4:$D$1266,2,FALSE) -> DSKBN | T23: 16 | AB23: =IF(L23="DELDTE","","○") -> ○ | AE23: =IF(AB23="○",IF(AH23="timestamp","now()",IF(LEFT(AH23,9)="character","' '","0")),"") -> ' ' | AH23: =VLOOKUP(D23,カラムID辞書!C:H,3,FALSE) -> character varying | AM23: =VLOOKUP(D23,カラムID辞書!C:H,4,FALSE) -> 1 | AO23: =VLOOKUP(D23,カラムID辞書!C:H,6,FALSE) -> 1 | AQ23: 0：プロパー / 1：セール
B24: =IF($D24="","",MAX(OFFSET($B$8,0,0,ROW()-ROW($B$8),2))+1) -> 17 | D24: 利益計算式区分 | L24: =VLOOKUP(D24,カラムID辞書!$C$4:$D$1266,2,FALSE) -> RIEKICMPKBN | T24: 17 | AB24: =IF(L24="DELDTE","","○") -> ○ | AE24: =IF(AB24="○",IF(AH24="timestamp","now()",IF(LEFT(AH24,9)="character","' '","0")),"") -> ' ' | AH24: =VLOOKUP(D24,カラムID辞書!C:H,3,FALSE) -> character varying | AM24: =VLOOKUP(D24,カラムID辞書!C:H,4,FALSE) -> 1 | AO24: =VLOOKUP(D24,カラムID辞書!C:H,6,FALSE) -> 1 | AQ24: 0：利益計算対象外 / 1：売価還元原価法 / 3：売仕原価計算 /7：原価品計算
B25: =IF($D25="","",MAX(OFFSET($B$8,0,0,ROW()-ROW($B$8),2))+1) -> 18 | D25: 年 | L25: =VLOOKUP(D25,カラムID辞書!$C$4:$D$1266,2,FALSE) -> NENDO | AB25: =IF(L25="DELDTE","","○") -> ○ | AE25: =IF(AB25="○",IF(AH25="timestamp","now()",IF(LEFT(AH25,9)="character","' '","0")),"") -> 0 | AH25: =VLOOKUP(D25,カラムID辞書!C:H,3,FALSE) -> numeric | AM25: =VLOOKUP(D25,カラムID辞書!C:H,4,FALSE) -> 6 | AO25: =VLOOKUP(D25,カラムID辞書!C:H,6,FALSE) -> 6 | AQ25: 「期」に該当する年度開始月（YYYYMM）
B26: =IF($D26="","",MAX(OFFSET($B$8,0,0,ROW()-ROW($B$8),2))+1) -> 19 | D26: 売上高原価 | L26: =VLOOKUP(D26,カラムID辞書!$C$4:$D$1266,2,FALSE) -> URIAGED_GNK | AB26: =IF(L26="DELDTE","","○") -> ○ | AE26: =IF(AB26="○",IF(AH26="timestamp","now()",IF(LEFT(AH26,9)="character","' '","0")),"") -> 0 | AH26: =VLOOKUP(D26,カラムID辞書!C:H,3,FALSE) -> numeric | AM26: =VLOOKUP(D26,カラムID辞書!C:H,4,FALSE) -> 13 | AO26: =VLOOKUP(D26,カラムID辞書!C:H,6,FALSE) -> 13 | AQ26: 別紙「商品勘定利益計算」参照
B27: =IF($D27="","",MAX(OFFSET($B$8,0,0,ROW()-ROW($B$8),2))+1) -> 20 | D27: 売上高売価 | L27: =VLOOKUP(D27,カラムID辞書!$C$4:$D$1266,2,FALSE) -> URIAGED_BIK | AB27: =IF(L27="DELDTE","","○") -> ○ | AE27: =IF(AB27="○",IF(AH27="timestamp","now()",IF(LEFT(AH27,9)="character","' '","0")),"") -> 0 | AH27: =VLOOKUP(D27,カラムID辞書!C:H,3,FALSE) -> numeric | AM27: =VLOOKUP(D27,カラムID辞書!C:H,4,FALSE) -> 13 | AO27: =VLOOKUP(D27,カラムID辞書!C:H,6,FALSE) -> 13 | AQ27: 売上伝票の売上高集計値（総売上高）
B28: =IF($D28="","",MAX(OFFSET($B$8,0,0,ROW()-ROW($B$8),2))+1) -> 21 | D28: 売上高分類１ | L28: =VLOOKUP(D28,カラムID辞書!$C$4:$D$1266,2,FALSE) -> URIAGED_BNRI1 | AB28: =IF(L28="DELDTE","","○") -> ○ | AE28: =IF(AB28="○",IF(AH28="timestamp","now()",IF(LEFT(AH28,9)="character","' '","0")),"") -> 0 | AH28: =VLOOKUP(D28,カラムID辞書!C:H,3,FALSE) -> numeric | AM28: =VLOOKUP(D28,カラムID辞書!C:H,4,FALSE) -> 13 | AO28: =VLOOKUP(D28,カラムID辞書!C:H,6,FALSE) -> 13 | AQ28: 売上伝票の売上高集計値（店頭・普通品）
B29: =IF($D29="","",MAX(OFFSET($B$8,0,0,ROW()-ROW($B$8),2))+1) -> 22 | D29: 売上高分類２ | L29: =VLOOKUP(D29,カラムID辞書!$C$4:$D$1266,2,FALSE) -> URIAGED_BNRI2 | AB29: =IF(L29="DELDTE","","○") -> ○ | AE29: =IF(AB29="○",IF(AH29="timestamp","now()",IF(LEFT(AH29,9)="character","' '","0")),"") -> 0 | AH29: =VLOOKUP(D29,カラムID辞書!C:H,3,FALSE) -> numeric | AM29: =VLOOKUP(D29,カラムID辞書!C:H,4,FALSE) -> 13 | AO29: =VLOOKUP(D29,カラムID辞書!C:H,6,FALSE) -> 13 | AQ29: 売上伝票の売上高集計値（店頭・催事）
B30: =IF($D30="","",MAX(OFFSET($B$8,0,0,ROW()-ROW($B$8),2))+1) -> 23 | D30: 売上高分類３ | L30: =VLOOKUP(D30,カラムID辞書!$C$4:$D$1266,2,FALSE) -> URIAGED_BNRI3 | AB30: =IF(L30="DELDTE","","○") -> ○ | AE30: =IF(AB30="○",IF(AH30="timestamp","now()",IF(LEFT(AH30,9)="character","' '","0")),"") -> 0 | AH30: =VLOOKUP(D30,カラムID辞書!C:H,3,FALSE) -> numeric | AM30: =VLOOKUP(D30,カラムID辞書!C:H,4,FALSE) -> 13 | AO30: =VLOOKUP(D30,カラムID辞書!C:H,6,FALSE) -> 13 | AQ30: 売上伝票の売上高集計値（店頭・店外）
B31: =IF($D31="","",MAX(OFFSET($B$8,0,0,ROW()-ROW($B$8),2))+1) -> 24 | D31: 売上高分類４ | L31: =VLOOKUP(D31,カラムID辞書!$C$4:$D$1266,2,FALSE) -> URIAGED_BNRI4 | AB31: =IF(L31="DELDTE","","○") -> ○ | AE31: =IF(AB31="○",IF(AH31="timestamp","now()",IF(LEFT(AH31,9)="character","' '","0")),"") -> 0 | AH31: =VLOOKUP(D31,カラムID辞書!C:H,3,FALSE) -> numeric | AM31: =VLOOKUP(D31,カラムID辞書!C:H,4,FALSE) -> 13 | AO31: =VLOOKUP(D31,カラムID辞書!C:H,6,FALSE) -> 13 | AQ31: 売上伝票の売上高集計値（店頭・ギフト）
B32: =IF($D32="","",MAX(OFFSET($B$8,0,0,ROW()-ROW($B$8),2))+1) -> 25 | D32: 売上高分類５ | L32: =VLOOKUP(D32,カラムID辞書!$C$4:$D$1266,2,FALSE) -> URIAGED_BNRI5 | AB32: =IF(L32="DELDTE","","○") -> ○ | AE32: =IF(AB32="○",IF(AH32="timestamp","now()",IF(LEFT(AH32,9)="character","' '","0")),"") -> 0 | AH32: =VLOOKUP(D32,カラムID辞書!C:H,3,FALSE) -> numeric | AM32: =VLOOKUP(D32,カラムID辞書!C:H,4,FALSE) -> 13 | AO32: =VLOOKUP(D32,カラムID辞書!C:H,6,FALSE) -> 13 | AQ32: 売上伝票の売上高集計値（店頭・ネット）
B33: =IF($D33="","",MAX(OFFSET($B$8,0,0,ROW()-ROW($B$8),2))+1) -> 26 | D33: 売上高分類６ | L33: =VLOOKUP(D33,カラムID辞書!$C$4:$D$1266,2,FALSE) -> URIAGED_BNRI6 | AB33: =IF(L33="DELDTE","","○") -> ○ | AE33: =IF(AB33="○",IF(AH33="timestamp","now()",IF(LEFT(AH33,9)="character","' '","0")),"") -> 0 | AH33: =VLOOKUP(D33,カラムID辞書!C:H,3,FALSE) -> numeric | AM33: =VLOOKUP(D33,カラムID辞書!C:H,4,FALSE) -> 13 | AO33: =VLOOKUP(D33,カラムID辞書!C:H,6,FALSE) -> 13 | AQ33: 売上伝票の売上高集計値（店頭・その他）
B34: =IF($D34="","",MAX(OFFSET($B$8,0,0,ROW()-ROW($B$8),2))+1) -> 27 | D34: 売上高分類７ | L34: =VLOOKUP(D34,カラムID辞書!$C$4:$D$1266,2,FALSE) -> URIAGED_BNRI7 | AB34: =IF(L34="DELDTE","","○") -> ○ | AE34: =IF(AB34="○",IF(AH34="timestamp","now()",IF(LEFT(AH34,9)="character","' '","0")),"") -> 0 | AH34: =VLOOKUP(D34,カラムID辞書!C:H,3,FALSE) -> numeric | AM34: =VLOOKUP(D34,カラムID辞書!C:H,4,FALSE) -> 13 | AO34: =VLOOKUP(D34,カラムID辞書!C:H,6,FALSE) -> 13 | AQ34: 売上伝票の売上高集計値（非店頭・店外）
B35: =IF($D35="","",MAX(OFFSET($B$8,0,0,ROW()-ROW($B$8),2))+1) -> 28 | D35: 売上高分類８ | L35: =VLOOKUP(D35,カラムID辞書!$C$4:$D$1266,2,FALSE) -> URIAGED_BNRI8 | AB35: =IF(L35="DELDTE","","○") -> ○ | AE35: =IF(AB35="○",IF(AH35="timestamp","now()",IF(LEFT(AH35,9)="character","' '","0")),"") -> 0 | AH35: =VLOOKUP(D35,カラムID辞書!C:H,3,FALSE) -> numeric | AM35: =VLOOKUP(D35,カラムID辞書!C:H,4,FALSE) -> 13 | AO35: =VLOOKUP(D35,カラムID辞書!C:H,6,FALSE) -> 13 | AQ35: 売上伝票の売上高集計値（非店頭・ギフト）
B36: =IF($D36="","",MAX(OFFSET($B$8,0,0,ROW()-ROW($B$8),2))+1) -> 29 | D36: 売上高分類９ | L36: =VLOOKUP(D36,カラムID辞書!$C$4:$D$1266,2,FALSE) -> URIAGED_BNRI9 | AB36: =IF(L36="DELDTE","","○") -> ○ | AE36: =IF(AB36="○",IF(AH36="timestamp","now()",IF(LEFT(AH36,9)="character","' '","0")),"") -> 0 | AH36: =VLOOKUP(D36,カラムID辞書!C:H,3,FALSE) -> numeric | AM36: =VLOOKUP(D36,カラムID辞書!C:H,4,FALSE) -> 13 | AO36: =VLOOKUP(D36,カラムID辞書!C:H,6,FALSE) -> 13 | AQ36: 売上伝票の売上高集計値（非店頭・その他）
B37: =IF($D37="","",MAX(OFFSET($B$8,0,0,ROW()-ROW($B$8),2))+1) -> 30 | D37: 売上高分類１０ | L37: =VLOOKUP(D37,カラムID辞書!$C$4:$D$1266,2,FALSE) -> URIAGED_BNRI10 | AB37: =IF(L37="DELDTE","","○") -> ○ | AE37: =IF(AB37="○",IF(AH37="timestamp","now()",IF(LEFT(AH37,9)="character","' '","0")),"") -> 0 | AH37: =VLOOKUP(D37,カラムID辞書!C:H,3,FALSE) -> numeric | AM37: =VLOOKUP(D37,カラムID辞書!C:H,4,FALSE) -> 13 | AO37: =VLOOKUP(D37,カラムID辞書!C:H,6,FALSE) -> 13 | BR37: （未設定：ZERO）
B38: =IF($D38="","",MAX(OFFSET($B$8,0,0,ROW()-ROW($B$8),2))+1) -> 31 | D38: 売上高数量 | L38: =VLOOKUP(D38,カラムID辞書!$C$4:$D$1266,2,FALSE) -> URIAGED_SU | AB38: =IF(L38="DELDTE","","○") -> ○ | AE38: =IF(AB38="○",IF(AH38="timestamp","now()",IF(LEFT(AH38,9)="character","' '","0")),"") -> 0 | AH38: =VLOOKUP(D38,カラムID辞書!C:H,3,FALSE) -> numeric | AM38: =VLOOKUP(D38,カラムID辞書!C:H,4,FALSE) -> 10 | AO38: =VLOOKUP(D38,カラムID辞書!C:H,6,FALSE) -> 10 | AQ38: 売上伝票の売上数量集計値
B39: =IF($D39="","",MAX(OFFSET($B$8,0,0,ROW()-ROW($B$8),2))+1) -> 32 | D39: 利益高 | L39: =VLOOKUP(D39,カラムID辞書!$C$4:$D$1266,2,FALSE) -> RIEKID | AB39: =IF(L39="DELDTE","","○") -> ○ | AE39: =IF(AB39="○",IF(AH39="timestamp","now()",IF(LEFT(AH39,9)="character","' '","0")),"") -> 0 | AH39: =VLOOKUP(D39,カラムID辞書!C:H,3,FALSE) -> numeric | AM39: =VLOOKUP(D39,カラムID辞書!C:H,4,FALSE) -> 13 | AO39: =VLOOKUP(D39,カラムID辞書!C:H,6,FALSE) -> 13 | AQ39: 別紙「商品勘定利益計算」参照 | BR39: 売益金
B40: =IF($D40="","",MAX(OFFSET($B$8,0,0,ROW()-ROW($B$8),2))+1) -> 33 | D40: 割引額 | L40: =VLOOKUP(D40,カラムID辞書!$C$4:$D$1266,2,FALSE) -> WARIBIKI_GAK | AB40: =IF(L40="DELDTE","","○") -> ○ | AE40: =IF(AB40="○",IF(AH40="timestamp","now()",IF(LEFT(AH40,9)="character","' '","0")),"") -> 0 | AH40: =VLOOKUP(D40,カラムID辞書!C:H,3,FALSE) -> numeric | AM40: =VLOOKUP(D40,カラムID辞書!C:H,4,FALSE) -> 13 | AO40: =VLOOKUP(D40,カラムID辞書!C:H,6,FALSE) -> 13 | AQ40: 売上伝票の割引額集計値
B41: =IF($D41="","",MAX(OFFSET($B$8,0,0,ROW()-ROW($B$8),2))+1) -> 34 | D41: 値引額 | L41: =VLOOKUP(D41,カラムID辞書!$C$4:$D$1266,2,FALSE) -> NEBIKI_GAK | AB41: =IF(L41="DELDTE","","○") -> ○ | AE41: =IF(AB41="○",IF(AH41="timestamp","now()",IF(LEFT(AH41,9)="character","' '","0")),"") -> 0 | AH41: =VLOOKUP(D41,カラムID辞書!C:H,3,FALSE) -> numeric | AM41: =VLOOKUP(D41,カラムID辞書!C:H,4,FALSE) -> 13 | AO41: =VLOOKUP(D41,カラムID辞書!C:H,6,FALSE) -> 13 | AQ41: 売上伝票の値引額集計値
B42: =IF($D42="","",MAX(OFFSET($B$8,0,0,ROW()-ROW($B$8),2))+1) -> 35 | D42: 客数１ | L42: =VLOOKUP(D42,カラムID辞書!$C$4:$D$1266,2,FALSE) -> KYAKU1_SU | AB42: =IF(L42="DELDTE","","○") -> ○ | AE42: =IF(AB42="○",IF(AH42="timestamp","now()",IF(LEFT(AH42,9)="character","' '","0")),"") -> 0 | AH42: =VLOOKUP(D42,カラムID辞書!C:H,3,FALSE) -> numeric | AM42: =VLOOKUP(D42,カラムID辞書!C:H,4,FALSE) -> 10,2 | AO42: =VLOOKUP(D42,カラムID辞書!C:H,6,FALSE) -> 10 | AQ42: 売上伝票の客数１集計値
B43: =IF($D43="","",MAX(OFFSET($B$8,0,0,ROW()-ROW($B$8),2))+1) -> 36 | D43: 客数２ | L43: =VLOOKUP(D43,カラムID辞書!$C$4:$D$1266,2,FALSE) -> KYAKU2_SU | AB43: =IF(L43="DELDTE","","○") -> ○ | AE43: =IF(AB43="○",IF(AH43="timestamp","now()",IF(LEFT(AH43,9)="character","' '","0")),"") -> 0 | AH43: =VLOOKUP(D43,カラムID辞書!C:H,3,FALSE) -> numeric | AM43: =VLOOKUP(D43,カラムID辞書!C:H,4,FALSE) -> 10,2 | AO43: =VLOOKUP(D43,カラムID辞書!C:H,6,FALSE) -> 10 | AQ43: 売上伝票の客数２集計値
...

Sheet 売価還元単位別年別実績
B2: ユーザインタフェース 設計書 | J2: サブシステム分類 | O2: ドキュメント ID | T2: ドキュメント名 | BK2: 更新者 | BN2: 最終更新日 | BR2: 履歴 | BT2: 作成者 | BW2: 作成日
J3: 商品勘定 | O3: 2.04 | T3: テーブル定義 | BR3: 第1版 | BT3: 富士通 | BW3: 42917
B5: 概念データ名／ID | J5: 売価還元単位別年別実績テーブル | U5: ／ | V5: LBT04_BAIKAN_Y | AD5: OID | AK5: 最大レコード長 | AR5: =ROUNDUP((27+ROUNDUP((MAX(B:B)-COUNTIF(AB:AB,"○"))/8,0)+IF(AF5="",0,4))/8,0)*8+SUM(AO8:AO1028) -> 1770 | AU5: Byte | AW5: 用途 | BB5: 商品勘定実績を年度単位で管理する。
B7: 項番 | D7: 項目論理名称 | L7: 項目物理名称 | T7: PKey | V7: IDX1 | X7: IDX2 | Z7: IDX3 | AB7: NOTNULL | AE7: DEFAULT | AH7: Type | AM7: 桁数 | AO7: Byte | AQ7: 項目説明 | BR7: 備考
B8: 1 | D8: 年 | L8: =VLOOKUP(D8,カラムID辞書!$C$4:$D$1266,2,FALSE) -> NENDO | T8: 1 | AB8: =IF(L8="DELDTE","","○") -> ○ | AE8: =IF(AB8="○",IF(AH8="timestamp","now()",IF(LEFT(AH8,9)="character","' '","0")),"") -> 0 | AH8: =VLOOKUP(D8,カラムID辞書!C:H,3,FALSE) -> numeric | AM8: =VLOOKUP(D8,カラムID辞書!C:H,4,FALSE) -> 6 | AO8: =VLOOKUP(D8,カラムID辞書!C:H,6,FALSE) -> 6 | AQ8: 伝票計上日に該当する期首月（YYYYMM）
